Workbook

Sheet Sheet1
A3: Row Labels | B3: Sum of Total9
A4: 801582 | B4: 768
A5: 801583 | B5: 379
A6: 801588 | B6: 845.2
A7: 801589 | B7: 128
A8: 801590 | B8: 262
A9: 801627 | B9: 434
A10: 801716 | B10: 630.75
A11: 801727 | B11: 0
A12: 801729 | B12: 188.5
A13: 801757 | B13: 291.65
A14: 801764 | B14: 187.85
A15: 801766 | B15: 124
... A3164: 821479 | B3164: 35
A3165: Grand Total | B3165: 720991.25

Sheet mtd sale
F1: Apr'22 | I1: May'22 | L1: June'22 | O1: July'22 | R1: Aug'22 | U1: Sep'22 | X1: Oct'22 | AA1: Nov'22 | AD1: Dec'22 | AG1: TOTAL
A2: Combined | B2: Retailer Code | C2: Retailer Desc- | D2: Concerned Dealer code | E2: Concerned Dealer Name | F2: Total | G2: WS | H2: PPCSS | I2: Total | J2: WS | K2: PPCSS | L2: Total | M2: WS | N2: PPCSS | O2: Total | P2: WS | Q2: PPCSS | R2: Total | S2: WS | T2: PPCSS | U2: Total | V2: WS | W2: PPCSS | X2: Total | Y2: WS | Z2: PPCSS | AA2: Total | AB2: WS | AC2: PPCSS | AD2: Total | AE2: WS | AF2: PPCSS | AG2: Total | AH2: WS | AI2: PPCSS | AJ2: Dist | AK2: AO | AL2: State | AM2: DOA
A3: =B3&D3 -> 804178119046 | B3: 804178 | C3: SHIV TRADERS | D3: 119046 | E3: GARG AGRO AGENCIES | F3: 0 | G3: 0 | H3: 0 | I3: 20 | J3: 0 | K3: 0 | L3: 0 | M3: 0 | N3: 0 | O3: 10 | P3: 9 | Q3: 0 | R3: 20 | S3: 0 | T3: 0 | U3: 0 | V3: 0 | W3: 0 | X3: 0 | Y3: 0 | Z3: 0 | AA3: 75 | AB3: 0 | AC3: 0 | AD3: 40 | AE3: 0 | AF3: 5 | AG3: =SUMIF($F$2:$AF$2,"Total",F3:AF3) -> 165 | AH3: =SUMIF($F$2:$AF$2,"WS",F3:AF3) -> 9 | AI3: =SUMIF($F$2:$AF$2,"PPCSS",F3:AF3) -> 5 | AJ3: ALWAR | AK3: ALWAR | AL3: RJ-JAIPUR | AM3: 42227
A4: =B4&D4 -> 804286119046 | B4: 804286 | C4: ASHWINI AND SONS | D4: 119046 | E4: GARG AGRO AGENCIES | F4: 61.5 | G4: 0 | H4: 0 | I4: 20 | J4: 0 | K4: 0 | L4: 76 | M4: 0 | N4: 0 | O4: 35 | P4: 0 | Q4: 10 | R4: 20 | S4: 0 | T4: 0 | U4: 45 | V4: 0 | W4: 0 | X4: 42 | Y4: 0 | Z4: 0 | AA4: 31 | AB4: 0 | AC4: 0 | AD4: 70 | AE4: 0 | AF4: 0 | AG4: =SUMIF($F$2:$AF$2,"Total",F4:AF4) -> 400.5 | AH4: =SUMIF($F$2:$AF$2,"WS",F4:AF4) -> 0 | AI4: =SUMIF($F$2:$AF$2,"PPCSS",F4:AF4) -> 10 | AJ4: ALWAR | AK4: ALWAR | AL4: RJ-JAIPUR | AM4: 42262
A5: =B5&D5 -> 804980171880 | B5: 804980 | C5: SHREE OM TRADING COMPANY | D5: 171880 | E5: BHUVAN AGENCIES | F5: 0 | G5: 0 | H5: 0 | I5: 0 | J5: 0 | K5: 0 | L5: 0 | M5: 0 | N5: 0 | O5: 0 | P5: 0 | Q5: 0 | R5: 0 | S5: 0 | T5: 0 | U5: 0 | V5: 0 | W5: 0 | X5: 0 | Y5: 0 | Z5: 0 | AA5: 0 | AB5: 0 | AC5: 0 | AD5: 0 | AE5: 0 | AF5: 0 | AG5: =SUMIF($F$2:$AF$2,"Total",F5:AF5) -> 0 | AH5: =SUMIF($F$2:$AF$2,"WS",F5:AF5) -> 0 | AI5: =SUMIF($F$2:$AF$2,"PPCSS",F5:AF5) -> 0 | AJ5: ALWAR | AK5: ALWAR | AL5: RJ-JAIPUR | AM5: 42485
A6: =B6&D6 -> 806430175288 | B6: 806430 | C6: SHUBHAM BUILDIERS | D6: 175288 | E6: LAXMI TRADERS | F6: 30 | G6: 0 | H6: 0 | I6: 0 | J6: 0 | K6: 0 | L6: 0 | M6: 0 | N6: 0 | O6: 0 | P6: 0 | Q6: 0 | R6: 0 | S6: 0 | T6: 0 | U6: 0 | V6: 0 | W6: 0 | X6: 0 | Y6: 0 | Z6: 0 | AA6: 0 | AB6: 0 | AC6: 0 | AD6: 0 | AE6: 0 | AF6: 0 | AG6: =SUMIF($F$2:$AF$2,"Total",F6:AF6) -> 30 | AH6: =SUMIF($F$2:$AF$2,"WS",F6:AF6) -> 0 | AI6: =SUMIF($F$2:$AF$2,"PPCSS",F6:AF6) -> 0 | AJ6: ALWAR | AK6: ALWAR | AL6: RJ-JAIPUR | AM6: 42892
A7: =B7&D7 -> 806430210619 | B7: 806430 | C7: SHUBHAM BUILDIERS | D7: 210619 | E7: JAGDAMBA TRADING CO | F7: 0 | G7: 0 | H7: 0 | I7: 50 | J7: 0 | K7: 0 | L7: 105 | M7: 0 | N7: 0 | O7: 85 | P7: 0 | Q7: 0 | R7: 90 | S7: 0 | T7: 0 | U7: 82 | V7: 0 | W7: 22 | X7: 43.5 | Y7: 36 | Z7: 0 | AA7: 55.55 | AB7: 0 | AC7: 0 | AD7: 83.25 | AE7: 0 | AF7: 50 | AG7: =SUMIF($F$2:$AF$2,"Total",F7:AF7) -> 594.3 | AH7: =SUMIF($F$2:$AF$2,"WS",F7:AF7) -> 36 | AI7: =SUMIF($F$2:$AF$2,"PPCSS",F7:AF7) -> 72 | AJ7: ALWAR | AK7: ALWAR | AL7: RJ-JAIPUR | AM7: 42892
A8: =B8&D8 -> 806431149765 | B8: 806431 | C8: SISODIYA TRADERS | D8: 149765 | E8: ARORA CEMENT AGENCY | F8: 20 | G8: 0 | H8: 0 | I8: 20 | J8: 0 | K8: 0 | L8: 30 | M8: 0 | N8: 0 | O8: 20 | P8: 0 | Q8: 0 | R8: 20 | S8: 0 | T8: 0 | U8: 15 | V8: 0 | W8: 0 | X8: 10 | Y8: 0 | Z8: 0 | AA8: 10 | AB8: 0 | AC8: 0 | AD8: 20 | AE8: 0 | AF8: 0 | AG8: =SUMIF($F$2:$AF$2,"Total",F8:AF8) -> 165 | AH8: =SUMIF($F$2:$AF$2,"WS",F8:AF8) -> 0 | AI8: =SUMIF($F$2:$AF$2,"PPCSS",F8:AF8) -> 0 | AJ8: ALWAR | AK8: ALWAR | AL8: RJ-JAIPUR | AM8: 42892
A9: =B9&D9 -> 806484148557 | B9: 806484 | C9: GUPTA CEMENT AGENCY | D9: 148557 | E9: MITALI ALLOYS PVT LTD | F9: 81.5 | G9: 0 | H9: 0 | I9: 61.5 | J9: 0 | K9: 0 | L9: 91.5 | M9: 3 | N9: 0 | O9: 67.8 | P9: 19 | Q9: 0 | R9: 29 | S9: 0 | T9: 0 | U9: 68 | V9: 0 | W9: 0 | X9: 36.5 | Y9: 0 | Z9: 0 | AA9: 108 | AB9: 6 | AC9: 0 | AD9: 187 | AE9: 16.5 | AF9: 0 | AG9: =SUMIF($F$2:$AF$2,"Total",F9:AF9) -> 730.8 | AH9: =SUMIF($F$2:$AF$2,"WS",F9:AF9) -> 44.5 | AI9: =SUMIF($F$2:$AF$2,"PPCSS",F9:AF9) -> 0 | AJ9: ALWAR | AK9: ALWAR | AL9: RJ-JAIPUR | AM9: 42906
A10: =B10&D10 -> 806487149765 | B10: 806487 | C10: BANWARI LAL PRAKESH CHAND | D10: 149765 | E10: ARORA CEMENT AGENCY | F10: 70 | G10: 0 | H10: 0 | I10: 60 | J10: 0 | K10: 0 | L10: 50 | M10: 0 | N10: 0 | O10: 45 | P10: 0 | Q10: 0 | R10: 30 | S10: 0 | T10: 10 | U10: 27.5 | V10: 0 | W10: 0 | X10: 14.85 | Y10: 4.85 | Z10: 0 | AA10: 20 | AB10: 0 | AC10: 0 | AD10: 85 | AE10: 0 | AF10: 0 | AG10: =SUMIF($F$2:$AF$2,"Total",F10:AF10) -> 402.35 | AH10: =SUMIF($F$2:$AF$2,"WS",F10:AF10) -> 4.85 | AI10: =SUMIF($F$2:$AF$2,"PPCSS",F10:AF10) -> 10 | AJ10: ALWAR | AK10: ALWAR | AL10: RJ-JAIPUR | AM10: 42906
A11: =B11&D11 -> 806615149765 | B11: 806615 | C11: MAVAR CEMENT AGENCY | D11: 149765 | E11: ARORA CEMENT AGENCY | F11: 20 | G11: 0 | H11: 0 | I11: 10 | J11: 0 | K11: 0 | L11: 20 | M11: 0 | N11: 0 | O11: 10 | P11: 0 | Q11: 0 | R11: 30 | S11: 0 | T11: 0 | U11: 7.5 | V11: 0 | W11: 0 | X11: 15.1 | Y11: 0 | Z11: 0 | AA11: 0 | AB11: 0 | AC11: 0 | AD11: 20 | AE11: 0 | AF11: 0 | AG11: =SUMIF($F$2:$AF$2,"Total",F11:AF11) -> 132.6 | AH11: =SUMIF($F$2:$AF$2,"WS",F11:AF11) -> 0 | AI11: =SUMIF($F$2:$AF$2,"PPCSS",F11:AF11) -> 0 | AJ11: ALWAR | AK11: ALWAR | AL11: RJ-JAIPUR | AM11: 42935
A12: =B12&D12 -> 806689149765 | B12: 806689 | C12: KAKA BUILDERS | D12: 149765 | E12: ARORA CEMENT AGENCY | F12: 0 | G12: 0 | H12: 0 | I12: 0 | J12: 0 | K12: 0 | L12: 0 | M12: 0 | N12: 0 | O12: 0 | P12: 0 | Q12: 0 | R12: 0 | S12: 0 | T12: 0 | U12: 0 | V12: 0 | W12: 0 | X12: 0 | Y12: 0 | Z12: 0 | AA12: 0 | AB12: 0 | AC12: 0 | AD12: 0 | AE12: 0 | AF12: 0 | AG12: =SUMIF($F$2:$AF$2,"Total",F12:AF12) -> 0 | AH12: =SUMIF($F$2:$AF$2,"WS",F12:AF12) -> 0 | AI12: =SUMIF($F$2:$AF$2,"PPCSS",F12:AF12) -> 0 | AJ12: ALWAR | AK12: ALWAR | AL12: RJ-JAIPUR | AM12: 42958
A13: =B13&D13 -> 806720172252 | B13: 806720 | C13: YADHWANSHI BUILDING MATERIAL | D13: 172252 | E13: GUPTA TRADERS | F13: 0 | G13: 0 | H13: 0 | I13: 0 | J13: 0 | K13: 0 | L13: 0 | M13: 0 | N13: 0 | O13: 0 | P13: 0 | Q13: 0 | R13: 0 | S13: 0 | T13: 0 | U13: 0 | V13: 0 | W13: 0 | X13: 0 | Y13: 0 | Z13: 0 | AA13: 0 | AB13: 0 | AC13: 0 | AD13: 0 | AE13: 0 | AF13: 0 | AG13: =SUMIF($F$2:$AF$2,"Total",F13:AF13) -> 0 | AH13: =SUMIF($F$2:$AF$2,"WS",F13:AF13) -> 0 | AI13: =SUMIF($F$2:$AF$2,"PPCSS",F13:AF13) -> 0 | AJ13: ALWAR | AK13: ALWAR | AL13: RJ-JAIPUR | AM13: 42964
A14: =B14&D14 -> 806721140927 | B14: 806721 | C14: TANVI CEMENT AGENCY | D14: 140927 | E14: SHIV CHARAN LAL RAKESH KUMAR | F14: 50 | G14: 0 | H14: 0 | I14: 40 | J14: 0 | K14: 0 | L14: 30 | M14: 0 | N14: 0 | O14: 55 | P14: 0 | Q14: 0 | R14: 52 | S14: 0 | T14: 0 | U14: 59 | V14: 0 | W14: 0 | X14: 50.6 | Y14: 9.6 | Z14: 7.5 | AA14: 32.5 | AB14: 0 | AC14: 7.5 | AD14: 70 | AE14: 0 | AF14: 0 | AG14: =SUMIF($F$2:$AF$2,"Total",F14:AF14) -> 439.1 | AH14: =SUMIF($F$2:$AF$2,"WS",F14:AF14) -> 9.6 | AI14: =SUMIF($F$2:$AF$2,"PPCSS",F14:AF14) -> 15 | AJ14: ALWAR | AK14: ALWAR | AL14: RJ-JAIPUR | AM14: 42964
... A112: =B112&D112 -> 818883211046 | B112: 818883 | C112: KUMAWAT BUILDING MATERIAL | D112: 211046 | E112: MAHALAXMI TRADING CO. | F112: 0 | G112: 0 | H112: 0 | I112: 0 | J112: 0 | K112: 0 | L112: 0 | M112: 0 | N112: 0 | O112: 15 | P112: 0 | Q112: 5 | R112: 20 | S112: 0 | T112: 8.25 | U112: 69.15 | V112: 0 | W112: 15 | X112: 34 | Y112: 0 | Z112: 10 | AA112: 36 | AB112: 0 | AC112: 6 | AD112: 68 | AE112: 0 | AF112: 17.5 | AG112: =SUMIF($F$2:$AF$2,"Total",F112:AF112) -> 242.15 | AH112: =SUMIF($F$2:$AF$2,"WS",F112:AF112) -> 0 | AI112: =SUMIF($F$2:$AF$2,"PPCSS",F112:AF112) -> 61.75 | AJ112: ALWAR | AK112: ALWAR | AL112: RJ-JAIPUR | AM112: 44690
A113: =B113&D113 -> 818883179893 | B113: 818883 | C113: KUMAWAT BUILDING MATERIAL | D113: 179893 | E113: AGRAWAL TRADERS | F113: 0 | G113: 0 | H113: 0 | I113: 0 | J113: 0 | K113: 0 | L113: 0 | M113: 0 | N113: 0 | O113: 0 | P113: 0 | Q113: 0 | R113: 10 | S113: 0 | T113: 0 | U113: 0 | V113: 0 | W113: 0 | X113: 0 | Y113: 0 | Z113: 0 | AA113: 0 | AB113: 0 | AC113: 0 | AD113: 0 | AE113: 0 | AF113: 0 | AG113: =SUMIF($F$2:$AF$2,"Total",F113:AF113) -> 10 | AH113: =SUMIF($F$2:$AF$2,"WS",F113:AF113) -> 0 | AI113: =SUMIF($F$2:$AF$2,"PPCSS",F113:AF113) -> 0 | AJ113: ALWAR | AK113: ALWAR | AL113: RJ-JAIPUR | AM113: 44690
A114: =B114&D114 -> 818884210696 | B114: 818884 | C114: AYAAN CEMENT AGENCY | D114: 210696 | E114: GURU SANITARY & HARDWARES | F114: 0 | G114: 0 | H114: 0 | I114: 20 | J114: 0 | K114: 0 | L114: 50 | M114: 0 | N114: 0 | O114: 50 | P114: 0 | Q114: 0 | R114: 41.25 | S114: 0.25 | T114: 0 | U114: 52.5 | V114: 0 | W114: 10 | X114: 98 | Y114: 13 | Z114: 17.5 | AA114: 65 | AB114: 0 | AC114: 0 | AD114: 71 | AE114: 0 | AF114: 0 | AG114: =SUMIF($F$2:$AF$2,"Total",F114:AF114) -> 447.75 | AH114: =SUMIF($F$2:$AF$2,"WS",F114:AF114) -> 13.25 | AI114: =SUMIF($F$2:$AF$2,"PPCSS",F114:AF114) -> 27.5 | AJ114: ALWAR | AK114: ALWAR | AL114: RJ-JAIPUR | AM114: 44690
A115: =B115&D115 -> 819325210619 | B115: 819325 | C115: JITENDRA KUMAR MOHIT KUMAR | D115: 210619 | E115: JAGDAMBA TRADING CO | F115: 0 | G115: 0 | H115: 0 | I115: 0 | J115: 0 | K115: 0 | L115: 0 | M115: 0 | N115: 0 | O115: 40 | P115: 0 | Q115: 0 | R115: 26 | S115: 0 | T115: 0 | U115: 15 | V115: 0 | W115: 0 | X115: 0 | Y115: 0 | Z115: 0 | AA115: 0 | AB115: 0 | AC115: 0 | AD115: 10 | AE115: 0 | AF115: 0 | AG115: =SUMIF($F$2:$AF$2,"Total",F115:AF115) -> 91 | AH115: =SUMIF($F$2:$AF$2,"WS",F115:AF115) -> 0 | AI115: =SUMIF($F$2:$AF$2,"PPCSS",F115:AF115) -> 0 | AJ115: ALWAR | AK115: ALWAR | AL115: RJ-JAIPUR | AM115: 44725
A116: =B116&D116 -> 819326210619 | B116: 819326 | C116: SHRI ROHITASH CEMENT AGENCY | D116: 210619 | E116: JAGDAMBA TRADING CO | F116: 0 | G116: 0 | H116: 0 | I116: 0 | J116: 0 | K116: 0 | L116: 15 | M116: 0 | N116: 0 | O116: 90 | P116: 10 | Q116: 0 | R116: 95 | S116: 10 | T116: 0 | U116: 102 | V116: 0 | W116: 0 | X116: 42.5 | Y116: 0 | Z116: 20 | AA116: 0 | AB116: 0 | AC116: 0 | AD116: 90.5 | AE116: 0 | AF116: 0 | AG116: =SUMIF($F$2:$AF$2,"Total",F116:AF116) -> 435 | AH116: =SUMIF($F$2:$AF$2,"WS",F116:AF116) -> 20 | AI116: =SUMIF($F$2:$AF$2,"PPCSS",F116:AF116) -> 20 | AJ116: ALWAR | AK116: ALWAR | AL116: RJ-JAIPUR | AM116: 44725
A117: =B117&D117 -> 819350210696 | B117: 819350 | C117: SHIV TRADERS | D117: 210696 | E117: GURU SANITARY & HARDWARES | F117: 0 | G117: 0 | H117: 0 | I117: 0 | J117: 0 | K117: 0 | L117: 70.05 | M117: 0 | N117: 7.55 | O117: 65 | P117: 0 | Q117: 0 | R117: 20 | S117: 0 | T117: 0 | U117: 98 | V117: 8.5 | W117: 9 | X117: 118.35 | Y117: 10 | Z117: 20.85 | AA117: 60 | AB117: 7.5 | AC117: 0 | AD117: 110 | AE117: 0 | AF117: 15 | AG117: =SUMIF($F$2:$AF$2,"Total",F117:AF117) -> 541.4 | AH117: =SUMIF($F$2:$AF$2,"WS",F117:AF117) -> 26 | AI117: =SUMIF($F$2:$AF$2,"PPCSS",F117:AF117) -> 52.4 | AJ117: ALWAR | AK117: ALWAR | AL117: RJ-JAIPUR | AM117: 44726
A118: =B118&D118 -> 819351210619 | B118: 819351 | C118: SATNAM BUIDLING MATERIAL SUPPL | D118: 210619 | E118: JAGDAMBA TRADING CO | F118: 0 | G118: 0 | H118: 0 | I118: 0 | J118: 0 | K118: 0 | L118: 0 | M118: 0 | N118: 0 | O118: 40 | P118: 0 | Q118: 0 | R118: 50 | S118: 0 | T118: 10 | U118: 0 | V118: 0 | W118: 0 | X118: 0 | Y118: 0 | Z118: 0 | AA118: 0 | AB118: 0 | AC118: 0 | AD118: 0 | AE118: 0 | AF118: 0 | AG118: =SUMIF($F$2:$AF$2,"Total",F118:AF118) -> 90 | AH118: =SUMIF($F$2:$AF$2,"WS",F118:AF118) -> 0 | AI118: =SUMIF($F$2:$AF$2,"PPCSS",F118:AF118) -> 10 | AJ118: ALWAR | AK118: ALWAR | AL118: RJ-JAIPUR | AM118: 44726
A119: =B119&D119 -> 819425210619 | B119: 819425 | C119: CHOUHAN CEMENT AGENCY | D119: 210619 | E119: JAGDAMBA TRADING CO | F119: 0 | G119: 0 | H119: 0 | I119: 0 | J119: 0 | K119: 0 | L119: 0 | M119: 0 | N119: 0 | O119: 0 | P119: 0 | Q119: 0 | R119: 15 | S119: 0 | T119: 0 | U119: 0 | V119: 0 | W119: 0 | X119: 0 | Y119: 0 | Z119: 0 | AA119: 0 | AB119: 0 | AC119: 0 | AD119: 0 | AE119: 0 | AF119: 0 | AG119: =SUMIF($F$2:$AF$2,"Total",F119:AF119) -> 15 | AH119: =SUMIF($F$2:$AF$2,"WS",F119:AF119) -> 0 | AI119: =SUMIF($F$2:$AF$2,"PPCSS",F119:AF119) -> 0 | AJ119: ALWAR | AK119: ALWAR | AL119: RJ-JAIPUR | AM119: 44732
A120: =B120&D120 -> 819901149765 | B120: 819901 | C120: SHREE BUILDERS | D120: 149765 | E120: ARORA CEMENT AGENCY | F120: 0 | G120: 0 | H120: 0 | I120: 0 | J120: 0 | K120: 0 | L120: 0 | M120: 0 | N120: 0 | O120: 0 | P120: 0 | Q120: 0 | R120: 10 | S120: 0 | T120: 0 | U120: 10 | V120: 0 | W120: 0 | X120: 20 | Y120: 0 | Z120: 0 | AA120: 17.5 | AB120: 0 | AC120: 0 | AD120: 40 | AE120: 0 | AF120: 0 | AG120: =SUMIF($F$2:$AF$2,"Total",F120:AF120) -> 97.5 | AH120: =SUMIF($F$2:$AF$2,"WS",F120:AF120) -> 0 | AI120: =SUMIF($F$2:$AF$2,"PPCSS",F120:AF120) -> 0 | AJ120: ALWAR | AK120: ALWAR | AL120: RJ-JAIPUR | AM120: 44765
A121: =B121&D121 -> 820092210619 | B121: 820092 | C121: MUKESH BUILDERS | D121: 210619 | E121: JAGDAMBA TRADING CO | F121: 0 | G121: 0 | H121: 0 | I121: 0 | J121: 0 | K121: 0 | L121: 0 | M121: 0 | N121: 0 | O121: 0 | P121: 0 | Q121: 0 | R121: 50 | S121: 0 | T121: 0 | U121: 58 | V121: 0 | W121: 0 | X121: 27.5 | Y121: 0 | Z121: 20 | AA121: 30 | AB121: 0 | AC121: 10 | AD121: 97 | AE121: 0 | AF121: 0 | AG121: =SUMIF($F$2:$AF$2,"Total",F121:AF121) -> 262.5 | AH121: =SUMIF($F$2:$AF$2,"WS",F121:AF121) -> 0 | AI121: =SUMIF($F$2:$AF$2,"PPCSS",F121:AF121) -> 30 | AJ121: ALWAR | AK121: ALWAR | AL121: RJ-JAIPUR | AM121: 44781
A122: =B122&D122 -> 820149148557 | B122: 820149 | C122: SAMARA BUILDING MATERIAL SUPPL | D122: 148557 | E122: MITALI ALLOYS PVT LTD | F122: 0 | G122: 0 | H122: 0 | I122: 0 | J122: 0 | K122: 0 | L122: 0 | M122: 0 | N122: 0 | O122: 0 | P122: 0 | Q122: 0 | R122: 30 | S122: 0 | T122: 0 | U122: 32.5 | V122: 0 | W122: 0 | X122: 46 | Y122: 0 | Z122: 0 | AA122: 110 | AB122: 0 | AC122: 0 | AD122: 212.35 | AE122: 0 | AF122: 0 | AG122: =SUMIF($F$2:$AF$2,"Total",F122:AF122) -> 430.85 | AH122: =SUMIF($F$2:$AF$2,"WS",F122:AF122) -> 0 | AI122: =SUMIF($F$2:$AF$2,"PPCSS",F122:AF122) -> 0 | AJ122: ALWAR | AK122: ALWAR | AL122: RJ-JAIPUR | AM122: 44790
A123: =B123&D123 -> 804980210696 | B123: 804980 | C123: SHREE OM TRADING COMPANY | D123: 210696 | E123: GURU SANITARY & HARDWARES | F123: 0 | G123: 0 | H123: 0 | I123: 0 | J123: 0 | K123: 0 | L123: 0 | M123: 0 | N123: 0 | O123: 0 | P123: 0 | Q123: 0 | R123: 0 | S123: 0 | T123: 0 | U123: 6.5 | V123: 0 | W123: 6.5 | X123: 0 | Y123: 0 | Z123: 0 | AA123: 0 | AB123: 0 | AC123: 0 | AD123: 0 | AE123: 0 | AF123: 0 | AG123: =SUMIF($F$2:$AF$2,"Total",F123:AF123) -> 6.5 | AH123: =SUMIF($F$2:$AF$2,"WS",F123:AF123) -> 0 | AI123: =SUMIF($F$2:$AF$2,"PPCSS",F123:AF123) -> 6.5 | AJ123: ALWAR | AK123: ALWAR | AL123: RJ-JAIPUR | AM123: 42485
A124: =B124&D124 -> 809569210696 | B124: 809569 | C124: DEVENDRA BUILDING MATERIAL | D124: 210696 | E124: GURU SANITARY & HARDWARES | F124: 0 | G124: 0 | H124: 0 | I124: 0 | J124: 0 | K124: 0 | L124: 0 | M124: 0 | N124: 0 | O124: 0 | P124: 0 | Q124: 0 | R124: 0 | S124: 0 | T124: 0 | U124: 5 | V124: 0 | W124: 0 | X124: 0 | Y124: 0 | Z124: 0 | AA124: 0 | AB124: 0 | AC124: 0 | AD124: 0 | AE124: 0 | AF124: 0 | AG124: =SUMIF($F$2:$AF$2,"Total",F124:AF124) -> 5 | AH124: =SUMIF($F$2:$AF$2,"WS",F124:AF124) -> 0 | AI124: =SUMIF($F$2:$AF$2,"PPCSS",F124:AF124) -> 0 | AJ124: ALWAR | AK124: ALWAR | AL124: RJ-JAIPUR | AM124: 43602
A125: =B125&D125 -> 811522210696 | B125: 811522 | C125: JASORIA DISTRIBUTORS | D125: 210696 | E125: GURU SANITARY & HARDWARES | F125: 0 | G125: 0 | H125: 0 | I125: 0 | J125: 0 | K125: 0 | L125: 0 | M125: 0 | N125: 0 | O125: 0 | P125: 0 | Q125: 0 | R125: 0 | S125: 0 | T125: 0 | U125: 5 | V125: 0 | W125: 5 | X125: 0 | Y125: 0 | Z125: 0 | AA125: 0 | AB125: 0 | AC125: 0 | AD125: 0 | AE125: 0 | AF125: 0 | AG125: =SUMIF($F$2:$AF$2,"Total",F125:AF125) -> 5 | AH125: =SUMIF($F$2:$AF$2,"WS",F125:AF125) -> 0 | AI125: =SUMIF($F$2:$AF$2,"PPCSS",F125:AF125) -> 5 | AJ125: ALWAR | AK125: ALWAR | AL125: RJ-JAIPUR | AM125: 43878
A126: =B126&D126 -> 818347202479 | B126: 818347 | C126: SHREE KRISHNA CEMENT AGENCY | D126: 202479 | E126: SHIKHA ENTERPRSIES | F126: 0 | G126: 0 | H126: 0 | I126: 0 | J126: 0 | K126: 0 | L126: 0 | M126: 0 | N126: 0 | O126: 0 | P126: 0 | Q126: 0 | R126: 0 | S126: 0 | T126: 0 | U126: 25 | V126: 0 | W126: 0 | X126: 0 | Y126: 0 | Z126: 0 | AA126: 0 | AB126: 0 | AC126: 0 | AD126: 0 | AE126: 0 | AF126: 0 | AG126: =SUMIF($F$2:$AF$2,"Total",F126:AF126) -> 25 | AH126: =SUMIF($F$2:$AF$2,"WS",F126:AF126) -> 0 | AI126: =SUMIF($F$2:$AF$2,"PPCSS",F126:AF126) -> 0 | AJ126: ALWAR | AK126: ALWAR | AL126: RJ-JAIPUR | AM126: 44632
A127: =B127&D127 -> 820460202479 | B127: 820460 | C127: SHREE KRISHNA CEMENT AGENCY | D127: 202479 | E127: SHIKHA ENTERPRSIES | F127: 0 | G127: 0 | H127: 0 | I127: 0 | J127: 0 | K127: 0 | L127: 0 | M127: 0 | N127: 0 | O127: 0 | P127: 0 | Q127: 0 | R127: 0 | S127: 0 | T127: 0 | U127: 50 | V127: 0 | W127: 7.5 | X127: 107.5 | Y127: 0 | Z127: 0 | AA127: 105.45 | AB127: 0 | AC127: 0 | AD127: 91 | AE127: 0 | AF127: 20 | AG127: =SUMIF($F$2:$AF$2,"Total",F127:AF127) -> 353.95 | AH127: =SUMIF($F$2:$AF$2,"WS",F127:AF127) -> 0 | AI127: =SUMIF($F$2:$AF$2,"PPCSS",F127:AF127) -> 27.5 | AJ127: ALWAR | AK127: ALWAR | AL127: RJ-JAIPUR | AM127: 44813
A128: =B128&D128 -> 820094142984 | B128: 820094 | C128: METHI BUILDERS | D128: 142984 | E128: JAGDAMBEY BUILDING MATERIAL SU | F128: 0 | G128: 0 | H128: 0 | I128: 0 | J128: 0 | K128: 0 | L128: 0 | M128: 0 | N128: 0 | O128: 0 | P128: 0 | Q128: 0 | R128: 0 | S128: 0 | T128: 0 | U128: 25 | V128: 0 | W128: 0 | X128: 0 | Y128: 0 | Z128: 0 | AA128: 0 | AB128: 0 | AC128: 0 | AD128: 0 | AE128: 0 | AF128: 0 | AG128: =SUMIF($F$2:$AF$2,"Total",F128:AF128) -> 25 | AH128: =SUMIF($F$2:$AF$2,"WS",F128:AF128) -> 0 | AI128: =SUMIF($F$2:$AF$2,"PPCSS",F128:AF128) -> 0 | AJ128: ALWAR | AK128: ALWAR | AL128: RJ-JAIPUR | AM128: 44781
A129: =B129&D129 -> 820288208736 | B129: 820288 | C129: JASRAM CEMENT AGENCY | D129: 208736 | E129: RAJORIYA TRADING COMPANY | F129: 0 | G129: 0 | H129: 0 | I129: 0 | J129: 0 | K129: 0 | L129: 0 | M129: 0 | N129: 0 | O129: 0 | P129: 0 | Q129: 0 | R129: 0 | S129: 0 | T129: 0 | U129: 15 | V129: 0 | W129: 0 | X129: 0 | Y129: 0 | Z129: 0 | AA129: 10 | AB129: 0 | AC129: 0 | AD129: 0 | AE129: 0 | AF129: 0 | AG129: =SUMIF($F$2:$AF$2,"Total",F129:AF129) -> 25 | AH129: =SUMIF($F$2:$AF$2,"WS",F129:AF129) -> 0 | AI129: =SUMIF($F$2:$AF$2,"PPCSS",F129:AF129) -> 0 | AJ129: ALWAR | AK129: ALWAR | AL129: RJ-JAIPUR | AM129: 44800
A130: =B130&D130 -> 820492212976 | B130: 820492 | C130: AMIT KHAD BEEJ BHANDAR | D130: 212976 | E130: CHOUDHARY BUILDERS | F130: 0 | G130: 0 | H130: 0 | I130: 0 | J130: 0 | K130: 0 | L130: 0 | M130: 0 | N130: 0 | O130: 0 | P130: 0 | Q130: 0 | R130: 0 | S130: 0 | T130: 0 | U130: 85 | V130: 0 | W130: 25 | X130: 116.3 | Y130: 8.8 | Z130: 0 | AA130: 118 | AB130: 15 | AC130: 18 | AD130: 138.6 | AE130: 0 | AF130: 0 | AG130: =SUMIF($F$2:$AF$2,"Total",F130:AF130) -> 457.9 | AH130: =SUMIF($F$2:$AF$2,"WS",F130:AF130) -> 23.8 | AI130: =SUMIF($F$2:$AF$2,"PPCSS",F130:AF130) -> 43 | AJ130: ALWAR | AK130: ALWAR | AL130: RJ-JAIPUR | AM130: 44817
A131: =B131&D131 -> 820484148557 | B131: 820484 | C131: ARIF CEMENT AGENCY | D131: 148557 | E131: MITALI ALLOYS PVT LTD | F131: 0 | G131: 0 | H131: 0 | I131: 0 | J131: 0 | K131: 0 | L131: 0 | M131: 0 | N131: 0 | O131: 0 | P131: 0 | Q131: 0 | R131: 0 | S131: 0 | T131: 0 | U131: 15 | V131: 0 | W131: 0 | X131: 0 | Y131: 0 | Z131: 0 | AA131: 28 | AB131: 0 | AC131: 0 | AD131: 22 | AE131: 0 | AF131: 0 | AG131: =SUMIF($F$2:$AF$2,"Total",F131:AF131) -> 65 | AH131: =SUMIF($F$2:$AF$2,"WS",F131:AF131) -> 0 | AI131: =SUMIF($F$2:$AF$2,"PPCSS",F131:AF131) -> 0 | AJ131: ALWAR | AK131: ALWAR | AL131: RJ-JAIPUR | AM131: 44816
... A221: =B221&D221 -> 818484179894 | B221: 818484 | C221: SURYANSH CEMENT AGENCY | D221: 179894 | E221: SHARMA CEMENT AGENCY | F221: 25 | G221: 0 | H221: 0 | I221: 0 | J221: 0 | K221: 0 | L221: 2.5 | M221: 0 | N221: 0 | O221: 5 | P221: 0 | Q221: 0 | R221: 0 | S221: 0 | T221: 0 | U221: 7.5 | V221: 0 | W221: 0 | X221: 5 | Y221: 0 | Z221: 0 | AA221: 0 | AB221: 0 | AC221: 0 | AD221: 0 | AE221: 0 | AF221: 0 | AG221: =SUMIF($F$2:$AF$2,"Total",F221:AF221) -> 45 | AH221: =SUMIF($F$2:$AF$2,"WS",F221:AF221) -> 0 | AI221: =SUMIF($F$2:$AF$2,"PPCSS",F221:AF221) -> 0 | AJ221: DHOLPUR | AK221: ALWAR | AL221: RJ-JAIPUR | AM221: 44646
A222: =B222&D222 -> 819817208516 | B222: 819817 | C222: BANKEY BIHARI TRADERS | D222: 208516 | E222: HARDENIYA CEMENT AGENCIES | F222: 0 | G222: 0 | H222: 0 | I222: 0 | J222: 0 | K222: 0 | L222: 0 | M222: 0 | N222: 0 | O222: 0 | P222: 0 | Q222: 0 | R222: 18 | S222: 0 | T222: 0 | U222: 22.5 | V222: 0 | W222: 0 | X222: 0 | Y222: 0 | Z222: 0 | AA222: 8 | AB222: 0 | AC222: 0 | AD222: 10 | AE222: 0 | AF222: 10 | AG222: =SUMIF($F$2:$AF$2,"Total",F222:AF222) -> 58.5 | AH222: =SUMIF($F$2:$AF$2,"WS",F222:AF222) -> 0 | AI222: =SUMIF($F$2:$AF$2,"PPCSS",F222:AF222) -> 10 | AJ222: DHOLPUR | AK222: ALWAR | AL222: RJ-JAIPUR | AM222: 44760
A223: =B223&D223 -> 820008179894 | B223: 820008 | C223: MANVENDRA CEMENT AGENCY | D223: 179894 | E223: SHARMA CEMENT AGENCY | F223: 0 | G223: 0 | H223: 0 | I223: 0 | J223: 0 | K223: 0 | L223: 0 | M223: 0 | N223: 0 | O223: 0 | P223: 0 | Q223: 0 | R223: 42.5 | S223: 0 | T223: 0 | U223: 20 | V223: 0 | W223: 0 | X223: 33 | Y223: 8 | Z223: 0 | AA223: 5 | AB223: 0 | AC223: 0 | AD223: 5 | AE223: 0 | AF223: 5 | AG223: =SUMIF($F$2:$AF$2,"Total",F223:AF223) -> 105.5 | AH223: =SUMIF($F$2:$AF$2,"WS",F223:AF223) -> 8 | AI223: =SUMIF($F$2:$AF$2,"PPCSS",F223:AF223) -> 5 | AJ223: DHOLPUR | AK223: ALWAR | AL223: RJ-JAIPUR | AM223: 44771
A224: =B224&D224 -> 820429210479 | B224: 820429 | C224: BALAJI BUILDING MATERIAL | D224: 210479 | E224: SHRIPATI CONSTRUCTION | F224: 0 | G224: 0 | H224: 0 | I224: 0 | J224: 0 | K224: 0 | L224: 0 | M224: 0 | N224: 0 | O224: 0 | P224: 0 | Q224: 0 | R224: 0 | S224: 0 | T224: 0 | U224: 54.5 | V224: 0 | W224: 6 | X224: 63 | Y224: 0 | Z224: 45 | AA224: 37.1 | AB224: 2.1 | AC224: 5 | AD224: 48 | AE224: 0 | AF224: 25 | AG224: =SUMIF($F$2:$AF$2,"Total",F224:AF224) -> 202.6 | AH224: =SUMIF($F$2:$AF$2,"WS",F224:AF224) -> 2.1 | AI224: =SUMIF($F$2:$AF$2,"PPCSS",F224:AF224) -> 81 | AJ224: DHOLPUR | AK224: ALWAR | AL224: RJ-JAIPUR | AM224: 44811
A225: =B225&D225 -> 820486179894 | B225: 820486 | C225: VANSHIKA CEMENT AGENCY | D225: 179894 | E225: SHARMA CEMENT AGENCY | F225: 0 | G225: 0 | H225: 0 | I225: 0 | J225: 0 | K225: 0 | L225: 0 | M225: 0 | N225: 0 | O225: 0 | P225: 0 | Q225: 0 | R225: 0 | S225: 0 | T225: 0 | U225: 21 | V225: 0 | W225: 0 | X225: 20 | Y225: 0 | Z225: 0 | AA225: 7.5 | AB225: 0 | AC225: 0 | AD225: 12.5 | AE225: 0 | AF225: 0 | AG225: =SUMIF($F$2:$AF$2,"Total",F225:AF225) -> 61 | AH225: =SUMIF($F$2:$AF$2,"WS",F225:AF225) -> 0 | AI225: =SUMIF($F$2:$AF$2,"PPCSS",F225:AF225) -> 0 | AJ225: DHOLPUR | AK225: ALWAR | AL225: RJ-JAIPUR | AM225: 44816
A226: =B226&D226 -> 820702179894 | B226: 820702 | C226: VIRENDRA CEMENT AGENCY | D226: 179894 | E226: SHARMA CEMENT AGENCY | F226: 0 | G226: 0 | H226: 0 | I226: 0 | J226: 0 | K226: 0 | L226: 0 | M226: 0 | N226: 0 | O226: 0 | P226: 0 | Q226: 0 | R226: 0 | S226: 0 | T226: 0 | U226: 0 | V226: 0 | W226: 0 | X226: 48 | Y226: 0 | Z226: 10 | AA226: 7.5 | AB226: 0 | AC226: 0 | AD226: 15 | AE226: 0 | AF226: 5 | AG226: =SUMIF($F$2:$AF$2,"Total",F226:AF226) -> 70.5 | AH226: =SUMIF($F$2:$AF$2,"WS",F226:AF226) -> 0 | AI226: =SUMIF($F$2:$AF$2,"PPCSS",F226:AF226) -> 15 | AJ226: DHOLPUR | AK226: ALWAR | AL226: RJ-JAIPUR | AM226: 44828
...

Sheet SCHEME
G8: Slab | H8: Tour
G9: 0 | H9: --- | I9: ---
G10: 400 | H10: Goa | I10: Slab-1
G11: 600 | H11: Kerala | I11: Slab-2
G12: 900 | H12: Thailand | I12: Slab-3
G13: 1200 | H13: Singapore | I13: Slab-4

Sheet SUMMARY
E3: Actutal till Feb 2022
C4: Annual Volume in MT | D4: Slab | E4: Qty. | F4: No of ARS
C6: <400 | D6: --- | E6: =SUMIF('mtd sale'!#REF!,SUMMARY!D6,'mtd sale'!#REF!) -> #REF! | F6: =COUNTIF('mtd sale'!#REF!,SUMMARY!D6) -> #REF!
C7: 400-599.99 | D7: Slab-1 | E7: =SUMIF('mtd sale'!#REF!,SUMMARY!D7,'mtd sale'!#REF!) -> #REF! | F7: =COUNTIF('mtd sale'!#REF!,SUMMARY!D7) -> #REF!
C8: 600-899.99 | D8: Slab-2 | E8: =SUMIF('mtd sale'!#REF!,SUMMARY!D8,'mtd sale'!#REF!) -> #REF! | F8: =COUNTIF('mtd sale'!#REF!,SUMMARY!D8) -> #REF!
C9: 900-1199.99 | D9: Slab-3 | E9: =SUMIF('mtd sale'!#REF!,SUMMARY!D9,'mtd sale'!#REF!) -> #REF! | F9: =COUNTIF('mtd sale'!#REF!,SUMMARY!D9) -> #REF!
C10: >=1200 | D10: Slab-4 | E10: =SUMIF('mtd sale'!#REF!,SUMMARY!D10,'mtd sale'!#REF!) -> #REF! | F10: =COUNTIF('mtd sale'!#REF!,SUMMARY!D10) -> #REF!
C11: Total | E11: =SUM(E6:E10) -> #REF! | F11: =SUM(F6:F10) -> #REF!
