Workbook

Sheet SUMMARY
C2: F.Y. 2020-21 (May'20-March'21) | G2: F.Y. 2021-22 (Apr'21-Oct'21) | K2: F.Y. 2022-23 (Apr'22-Oct'22)
B3: DIST. | C3: Total O/S | D3: Total Billing Value | E3: Total sale | F3: Avg. DSO | G3: Total O/S | H3: Total Billing Value | I3: Total sale | J3: Avg. DSO | K3: Total O/S | L3: Total Billing Value | M3: Total sale | N3: Avg. DSO
B4: ALWAR | C4: =SUMIFS('DSO FY 20-21'!AY:AY,'DSO FY 20-21'!$BC:$BC,SUMMARY!$B4) -> 1.1884024e+08 | D4: =SUMIFS('DSO FY 20-21'!BA:BA,'DSO FY 20-21'!$BC:$BC,SUMMARY!$B4) -> 5.8534367e+08 | E4: =SUMIFS('DSO FY 20-21'!AZ:AZ,'DSO FY 20-21'!$BC:$BC,SUMMARY!$B4) -> 81164.25 | F4: =IFERROR(C4/(D4/31),0) -> 6.2938194 | G4: =SUMIFS('DSO FY 21-22'!AY:AY,'DSO FY 21-22'!BC:BC,SUMMARY!B4) -> 85668872 | H4: =SUMIFS('DSO FY 21-22'!AZ:AZ,'DSO FY 21-22'!BC:BC,SUMMARY!B4) -> 4.4376164e+08 | I4: =SUMIFS('DSO FY 21-22'!BA:BA,'DSO FY 21-22'!BC:BC,SUMMARY!B4) -> 116722.3 | J4: =IFERROR(G4/(H4/31),0) -> 5.984598 | K4: =SUMIFS('DSO FY 22-23'!AY:AY,'DSO FY 22-23'!BC:BC,SUMMARY!B4) -> 1.6560557e+08 | L4: =SUMIFS('DSO FY 22-23'!AZ:AZ,'DSO FY 22-23'!BC:BC,SUMMARY!B4) -> 812076616 | M4: =SUMIFS('DSO FY 22-23'!BA:BA,'DSO FY 22-23'!BC:BC,SUMMARY!B4) -> 108320.25 | N4: =IFERROR(K4/(L4/31),0) -> 6.3217835
B5: BHARATPUR | C5: =SUMIFS('DSO FY 20-21'!AY:AY,'DSO FY 20-21'!BC:BC,SUMMARY!B5) -> 9524866.5 | D5: =SUMIFS('DSO FY 20-21'!BA:BA,'DSO FY 20-21'!$BC:$BC,SUMMARY!$B5) -> 368795925 | E5: =SUMIFS('DSO FY 20-21'!AZ:AZ,'DSO FY 20-21'!$BC:$BC,SUMMARY!$B5) -> 50702.9 | F5: =IFERROR(C5/(D5/31),0) -> 0.80063483 | G5: =SUMIFS('DSO FY 21-22'!AY:AY,'DSO FY 21-22'!BC:BC,SUMMARY!B5) -> 9711646.2 | H5: =SUMIFS('DSO FY 21-22'!AZ:AZ,'DSO FY 21-22'!BC:BC,SUMMARY!B5) -> 267507174 | I5: =SUMIFS('DSO FY 21-22'!BA:BA,'DSO FY 21-22'!BC:BC,SUMMARY!B5) -> 66779.35 | J5: =IFERROR(G5/(H5/31),0) -> 1.1254316 | K5: =SUMIFS('DSO FY 22-23'!AY:AY,'DSO FY 22-23'!BC:BC,SUMMARY!B5) -> 983256.85 | L5: =SUMIFS('DSO FY 22-23'!AZ:AZ,'DSO FY 22-23'!BC:BC,SUMMARY!B5) -> 3.9883268e+08 | M5: =SUMIFS('DSO FY 22-23'!BA:BA,'DSO FY 22-23'!BC:BC,SUMMARY!B5) -> 52656.55 | N5: =IFERROR(K5/(L5/31),0) -> 0.076425438
B6: DHOLPUR | C6: =SUMIFS('DSO FY 20-21'!AY:AY,'DSO FY 20-21'!BC:BC,SUMMARY!B6) -> 15361742 | D6: =SUMIFS('DSO FY 20-21'!BA:BA,'DSO FY 20-21'!$BC:$BC,SUMMARY!$B6) -> 41251060 | E6: =SUMIFS('DSO FY 20-21'!AZ:AZ,'DSO FY 20-21'!$BC:$BC,SUMMARY!$B6) -> 5846.85 | F6: =IFERROR(C6/(D6/31),0) -> 11.544286 | G6: =SUMIFS('DSO FY 21-22'!AY:AY,'DSO FY 21-22'!BC:BC,SUMMARY!B6) -> 23781675 | H6: =SUMIFS('DSO FY 21-22'!AZ:AZ,'DSO FY 21-22'!BC:BC,SUMMARY!B6) -> 35453818 | I6: =SUMIFS('DSO FY 21-22'!BA:BA,'DSO FY 21-22'!BC:BC,SUMMARY!B6) -> 10244.2 | J6: =IFERROR(G6/(H6/31),0) -> 20.794148 | K6: =SUMIFS('DSO FY 22-23'!AY:AY,'DSO FY 22-23'!BC:BC,SUMMARY!B6) -> 48390038 | L6: =SUMIFS('DSO FY 22-23'!AZ:AZ,'DSO FY 22-23'!BC:BC,SUMMARY!B6) -> 84659876 | M6: =SUMIFS('DSO FY 22-23'!BA:BA,'DSO FY 22-23'!BC:BC,SUMMARY!B6) -> 11588.25 | N6: =IFERROR(K6/(L6/31),0) -> 17.719034
B7: ALWAR AO | C7: =SUM(C4:C6) -> 1.4372685e+08 | D7: =SUM(D4:D6) -> 995390652 | E7: =SUM(E4:E6) -> 137714 | F7: =IFERROR(C7/(D7/31),0) -> 4.4761644 | G7: =SUM(G4:G6) -> 1.1916219e+08 | H7: =SUM(H4:H6) -> 7.4672263e+08 | I7: =SUM(I4:I6) -> 193745.85 | J7: =IFERROR(G7/(H7/31),0) -> 4.9469881 | K7: =SUM(K4:K6) -> 2.1497886e+08 | L7: =SUM(L4:L6) -> 1295569174 | M7: =SUM(M4:M6) -> 172565.05 | N7: =IFERROR(K7/(L7/31),0) -> 5.1439513
B8: JAIPUR URBAN | C8: =SUMIFS('DSO FY 20-21'!AY:AY,'DSO FY 20-21'!BC:BC,SUMMARY!B8) -> 34777933 | D8: =SUMIFS('DSO FY 20-21'!BA:BA,'DSO FY 20-21'!$BC:$BC,SUMMARY!$B8) -> 456121070 | E8: =SUMIFS('DSO FY 20-21'!AZ:AZ,'DSO FY 20-21'!$BC:$BC,SUMMARY!$B8) -> 64992 | F8: =IFERROR(C8/(D8/31),0) -> 2.3636617 | G8: =SUMIFS('DSO FY 21-22'!AY:AY,'DSO FY 21-22'!BC:BC,SUMMARY!B8) -> 38166187 | H8: =SUMIFS('DSO FY 21-22'!AZ:AZ,'DSO FY 21-22'!BC:BC,SUMMARY!B8) -> 3.705608e+08 | I8: =SUMIFS('DSO FY 21-22'!BA:BA,'DSO FY 21-22'!BC:BC,SUMMARY!B8) -> 108808.55 | J8: =IFERROR(G8/(H8/31),0) -> 3.1928682 | K8: =SUMIFS('DSO FY 22-23'!AY:AY,'DSO FY 22-23'!BC:BC,SUMMARY!B8) -> 1.1341246e+08 | L8: =SUMIFS('DSO FY 22-23'!AZ:AZ,'DSO FY 22-23'!BC:BC,SUMMARY!B8) -> 8.489036e+08 | M8: =SUMIFS('DSO FY 22-23'!BA:BA,'DSO FY 22-23'!BC:BC,SUMMARY!B8) -> 117242.85 | N8: =IFERROR(K8/(L8/31),0) -> 4.1415611
B9: JAIPUR URBAN | C9: =SUM(C8) -> 34777933 | D9: =SUM(D8) -> 456121070 | E9: =SUM(E8) -> 64992 | F9: =IFERROR(C9/(D9/31),0) -> 2.3636617 | G9: =SUM(G8) -> 38166187 | H9: =SUM(H8) -> 3.705608e+08 | I9: =SUM(I8) -> 108808.55 | J9: =IFERROR(G9/(H9/31),0) -> 3.1928682 | K9: =SUM(K8) -> 1.1341246e+08 | L9: =SUM(L8) -> 8.489036e+08 | M9: =SUM(M8) -> 117242.85 | N9: =IFERROR(K9/(L9/31),0) -> 4.1415611
B10: DAUSA | C10: =SUMIFS('DSO FY 20-21'!AY:AY,'DSO FY 20-21'!BC:BC,SUMMARY!B10) -> 21008426 | D10: =SUMIFS('DSO FY 20-21'!BA:BA,'DSO FY 20-21'!$BC:$BC,SUMMARY!$B10) -> 127561160 | E10: =SUMIFS('DSO FY 20-21'!AZ:AZ,'DSO FY 20-21'!$BC:$BC,SUMMARY!$B10) -> 17967.6 | F10: =IFERROR(C10/(D10/31),0) -> 5.105482 | G10: =SUMIFS('DSO FY 21-22'!AY:AY,'DSO FY 21-22'!BC:BC,SUMMARY!B10) -> 14880630 | H10: =SUMIFS('DSO FY 21-22'!AZ:AZ,'DSO FY 21-22'!BC:BC,SUMMARY!B10) -> 87013692 | I10: =SUMIFS('DSO FY 21-22'!BA:BA,'DSO FY 21-22'!BC:BC,SUMMARY!B10) -> 23369.3 | J10: =IFERROR(G10/(H10/31),0) -> 5.3014591 | K10: =SUMIFS('DSO FY 22-23'!AY:AY,'DSO FY 22-23'!BC:BC,SUMMARY!B10) -> 35234040 | L10: =SUMIFS('DSO FY 22-23'!AZ:AZ,'DSO FY 22-23'!BC:BC,SUMMARY!B10) -> 1.9442178e+08 | M10: =SUMIFS('DSO FY 22-23'!BA:BA,'DSO FY 22-23'!BC:BC,SUMMARY!B10) -> 26436.05 | N10: =IFERROR(K10/(L10/31),0) -> 5.6179676
B11: JAIPUR RURAL | C11: =SUMIFS('DSO FY 20-21'!AY:AY,'DSO FY 20-21'!BC:BC,SUMMARY!B11) -> 63633727 | D11: =SUMIFS('DSO FY 20-21'!BA:BA,'DSO FY 20-21'!$BC:$BC,SUMMARY!$B11) -> 196483645 | E11: =SUMIFS('DSO FY 20-21'!AZ:AZ,'DSO FY 20-21'!$BC:$BC,SUMMARY!$B11) -> 29223.35 | F11: =IFERROR(C11/(D11/31),0) -> 10.039744 | G11: =SUMIFS('DSO FY 21-22'!AY:AY,'DSO FY 21-22'!BC:BC,SUMMARY!B11) -> 77140823 | H11: =SUMIFS('DSO FY 21-22'!AZ:AZ,'DSO FY 21-22'!BC:BC,SUMMARY!B11) -> 187295578 | I11: =SUMIFS('DSO FY 21-22'!BA:BA,'DSO FY 21-22'!BC:BC,SUMMARY!B11) -> 52705.9 | J11: =IFERROR(G11/(H11/31),0) -> 12.76787 | K11: =SUMIFS('DSO FY 22-23'!AY:AY,'DSO FY 22-23'!BC:BC,SUMMARY!B11) -> 1.7332497e+08 | L11: =SUMIFS('DSO FY 22-23'!AZ:AZ,'DSO FY 22-23'!BC:BC,SUMMARY!B11) -> 447867829 | M11: =SUMIFS('DSO FY 22-23'!BA:BA,'DSO FY 22-23'!BC:BC,SUMMARY!B11) -> 61533.45 | N11: =IFERROR(K11/(L11/31),0) -> 11.997008
B12: JAIPUR RURAL | C12: =SUM(C10:C11) -> 84642152 | D12: =SUM(D10:D11) -> 324044805 | E12: =SUM(E10:E11) -> 47190.95 | F12: =IFERROR(C12/(D12/31),0) -> 8.0973578 | G12: =SUM(G10:G11) -> 92021453 | H12: =SUM(H10:H11) -> 274309270 | I12: =SUM(I10:I11) -> 76075.2 | J12: =IFERROR(G12/(H12/31),0) -> 10.399448 | K12: =SUM(K10:K11) -> 2.0855901e+08 | L12: =SUM(L10:L11) -> 6.4228961e+08 | M12: =SUM(M10:M11) -> 87969.5 | N12: =IFERROR(K12/(L12/31),0) -> 10.066065
B13: RJ JAIPUR | C13: =SUM(C12,C9,C7) -> 2.6314693e+08 | D13: =SUM(D12,D9,D7) -> 1775556527 | E13: =SUM(E12,E9,E7) -> 249896.95 | F13: =IFERROR(C13/(D13/31),0) -> 4.5943651 | G13: =SUM(G12,G9,G7) -> 2.4934983e+08 | H13: =SUM(H12,H9,H7) -> 1391592701 | I13: =SUM(I12,I9,I7) -> 378629.6 | J13: =IFERROR(G13/(H13/31),0) -> 5.5546748 | K13: =SUM(K12,K9,K7) -> 5.3695032e+08 | L13: =SUM(L12,L9,L7) -> 2786762384 | M13: =SUM(M12,M9,M7) -> 377777.4 | N13: =IFERROR(K13/(L13/31),0) -> 5.9730461
B14: BARMER | C14: =SUMIFS('DSO FY 20-21'!AY:AY,'DSO FY 20-21'!BC:BC,SUMMARY!B14) -> 77231732 | D14: =SUMIFS('DSO FY 20-21'!BA:BA,'DSO FY 20-21'!$BC:$BC,SUMMARY!$B14) -> 2.81377e+08 | E14: =SUMIFS('DSO FY 20-21'!AZ:AZ,'DSO FY 20-21'!$BC:$BC,SUMMARY!$B14) -> 38917.85 | F14: =IFERROR(C14/(D14/31),0) -> 8.5088107 | G14: =SUMIFS('DSO FY 21-22'!AY:AY,'DSO FY 21-22'!BC:BC,SUMMARY!B14) -> 65853502 | H14: =SUMIFS('DSO FY 21-22'!AZ:AZ,'DSO FY 21-22'!BC:BC,SUMMARY!B14) -> 211507090 | I14: =SUMIFS('DSO FY 21-22'!BA:BA,'DSO FY 21-22'!BC:BC,SUMMARY!B14) -> 53356.45 | J14: =IFERROR(G14/(H14/31),0) -> 9.6519628 | K14: =SUMIFS('DSO FY 22-23'!AY:AY,'DSO FY 22-23'!BC:BC,SUMMARY!B14) -> 0 | L14: =SUMIFS('DSO FY 22-23'!AZ:AZ,'DSO FY 22-23'!BC:BC,SUMMARY!B14) -> 0 | M14: =SUMIFS('DSO FY 22-23'!BA:BA,'DSO FY 22-23'!BC:BC,SUMMARY!B14) -> 0 | N14: =IFERROR(K14/(L14/31),0) -> 0
B15: JAISALMER | C15: =SUMIFS('DSO FY 20-21'!AY:AY,'DSO FY 20-21'!BC:BC,SUMMARY!B15) -> 3986551.5 | D15: =SUMIFS('DSO FY 20-21'!BA:BA,'DSO FY 20-21'!$BC:$BC,SUMMARY!$B15) -> 65656180 | E15: =SUMIFS('DSO FY 20-21'!AZ:AZ,'DSO FY 20-21'!$BC:$BC,SUMMARY!$B15) -> 9096 | F15: =IFERROR(C15/(D15/31),0) -> 1.8822767 | G15: =SUMIFS('DSO FY 21-22'!AY:AY,'DSO FY 21-22'!BC:BC,SUMMARY!B15) -> 7903194 | H15: =SUMIFS('DSO FY 21-22'!AZ:AZ,'DSO FY 21-22'!BC:BC,SUMMARY!B15) -> 54122580 | I15: =SUMIFS('DSO FY 21-22'!BA:BA,'DSO FY 21-22'!BC:BC,SUMMARY!B15) -> 14360 | J15: =IFERROR(G15/(H15/31),0) -> 4.5267431 | K15: =SUMIFS('DSO FY 22-23'!AY:AY,'DSO FY 22-23'!BC:BC,SUMMARY!B15) -> 0 | L15: =SUMIFS('DSO FY 22-23'!AZ:AZ,'DSO FY 22-23'!BC:BC,SUMMARY!B15) -> 0 | M15: =SUMIFS('DSO FY 22-23'!BA:BA,'DSO FY 22-23'!BC:BC,SUMMARY!B15) -> 0 | N15: =IFERROR(K15/(L15/31),0) -> 0
B16: BARMER AO | C16: =SUM(C14:C15) -> 81218283 | D16: =SUM(D14:D15) -> 3.4703318e+08 | E16: =SUM(E14:E15) -> 48013.85 | F16: =IFERROR(C16/(D16/31),0) -> 7.2551182 | G16: =SUM(G14:G15) -> 73756696 | H16: =SUM(H14:H15) -> 265629670 | I16: =SUM(I14:I15) -> 67716.45 | J16: =IFERROR(G16/(H16/31),0) -> 8.6076889 | K16: =SUM(K14:K15) -> 0 | L16: =SUM(L14:L15) -> 0 | M16: =SUM(M14:M15) -> 0 | N16: =IFERROR(K16/(L16/31),0) -> 0
B17: JODHPUR | C17: =SUMIFS('DSO FY 20-21'!AY:AY,'DSO FY 20-21'!BC:BC,SUMMARY!B17) -> 2.8388555e+08 | D17: =SUMIFS('DSO FY 20-21'!BA:BA,'DSO FY 20-21'!$BC:$BC,SUMMARY!$B17) -> 764723390 | E17: =SUMIFS('DSO FY 20-21'!AZ:AZ,'DSO FY 20-21'!$BC:$BC,SUMMARY!$B17) -> 104297.9 | F17: =IFERROR(C17/(D17/31),0) -> 11.50802 | G17: =SUMIFS('DSO FY 21-22'!AY:AY,'DSO FY 21-22'!BC:BC,SUMMARY!B17) -> 2.8452441e+08 | H17: =SUMIFS('DSO FY 21-22'!AZ:AZ,'DSO FY 21-22'!BC:BC,SUMMARY!B17) -> 474238103 | I17: =SUMIFS('DSO FY 21-22'!BA:BA,'DSO FY 21-22'!BC:BC,SUMMARY!B17) -> 118800.05 | J17: =IFERROR(G17/(H17/31),0) -> 18.598794 | K17: =SUMIFS('DSO FY 22-23'!AY:AY,'DSO FY 22-23'!BC:BC,SUMMARY!B17) -> 0 | L17: =SUMIFS('DSO FY 22-23'!AZ:AZ,'DSO FY 22-23'!BC:BC,SUMMARY!B17) -> 0 | M17: =SUMIFS('DSO FY 22-23'!BA:BA,'DSO FY 22-23'!BC:BC,SUMMARY!B17) -> 0 | N17: =IFERROR(K17/(L17/31),0) -> 0
B18: NAGAUR | C18: =SUMIFS('DSO FY 20-21'!AY:AY,'DSO FY 20-21'!BC:BC,SUMMARY!B18) -> 51610195 | D18: =SUMIFS('DSO FY 20-21'!BA:BA,'DSO FY 20-21'!$BC:$BC,SUMMARY!$B18) -> 166026750 | E18: =SUMIFS('DSO FY 20-21'!AZ:AZ,'DSO FY 20-21'!$BC:$BC,SUMMARY!$B18) -> 23093.75 | F18: =IFERROR(C18/(D18/31),0) -> 9.6364957 | G18: =SUMIFS('DSO FY 21-22'!AY:AY,'DSO FY 21-22'!BC:BC,SUMMARY!B18) -> 49867314 | H18: =SUMIFS('DSO FY 21-22'!AZ:AZ,'DSO FY 21-22'!BC:BC,SUMMARY!B18) -> 115281283 | I18: =SUMIFS('DSO FY 21-22'!BA:BA,'DSO FY 21-22'!BC:BC,SUMMARY!B18) -> 30406.95 | J18: =IFERROR(G18/(H18/31),0) -> 13.409694 | K18: =SUMIFS('DSO FY 22-23'!AY:AY,'DSO FY 22-23'!BC:BC,SUMMARY!B18) -> 0 | L18: =SUMIFS('DSO FY 22-23'!AZ:AZ,'DSO FY 22-23'!BC:BC,SUMMARY!B18) -> 0 | M18: =SUMIFS('DSO FY 22-23'!BA:BA,'DSO FY 22-23'!BC:BC,SUMMARY!B18) -> 0 | N18: =IFERROR(K18/(L18/31),0) -> 0
B19: JODHPUR AO | C19: =SUM(C17:C18) -> 3.3549575e+08 | D19: =SUM(D17:D18) -> 930750140 | E19: =SUM(E17:E18) -> 127391.65 | F19: =IFERROR(C19/(D19/31),0) -> 11.174178 | G19: =SUM(G17:G18) -> 3.3439172e+08 | H19: =SUM(H17:H18) -> 589519386 | I19: =SUM(I17:I18) -> 149207 | J19: =IFERROR(G19/(H19/31),0) -> 17.584058 | K19: =SUM(K17:K18) -> 0 | L19: =SUM(L17:L18) -> 0 | M19: =SUM(M17:M18) -> 0 | N19: =IFERROR(K19/(L19/31),0) -> 0
B20: JALORE | C20: =SUMIFS('DSO FY 20-21'!AY:AY,'DSO FY 20-21'!BC:BC,SUMMARY!B20) -> 72349625 | D20: =SUMIFS('DSO FY 20-21'!BA:BA,'DSO FY 20-21'!$BC:$BC,SUMMARY!$B20) -> 2.2721538e+08 | E20: =SUMIFS('DSO FY 20-21'!AZ:AZ,'DSO FY 20-21'!$BC:$BC,SUMMARY!$B20) -> 31907.35 | F20: =IFERROR(C20/(D20/31),0) -> 9.8709795 | G20: =SUMIFS('DSO FY 21-22'!AY:AY,'DSO FY 21-22'!BC:BC,SUMMARY!B20) -> 59136734 | H20: =SUMIFS('DSO FY 21-22'!AZ:AZ,'DSO FY 21-22'!BC:BC,SUMMARY!B20) -> 1.8178749e+08 | I20: =SUMIFS('DSO FY 21-22'!BA:BA,'DSO FY 21-22'!BC:BC,SUMMARY!B20) -> 47936.1 | J20: =IFERROR(G20/(H20/31),0) -> 10.084515 | K20: =SUMIFS('DSO FY 22-23'!AY:AY,'DSO FY 22-23'!BC:BC,SUMMARY!B20) -> 0 | L20: =SUMIFS('DSO FY 22-23'!AZ:AZ,'DSO FY 22-23'!BC:BC,SUMMARY!B20) -> 0 | M20: =SUMIFS('DSO FY 22-23'!BA:BA,'DSO FY 22-23'!BC:BC,SUMMARY!B20) -> 0 | N20: =IFERROR(K20/(L20/31),0) -> 0
B21: PALI | C21: =SUMIFS('DSO FY 20-21'!AY:AY,'DSO FY 20-21'!BC:BC,SUMMARY!B21) -> 19683113 | D21: =SUMIFS('DSO FY 20-21'!BA:BA,'DSO FY 20-21'!$BC:$BC,SUMMARY!$B21) -> 2.1196184e+08 | E21: =SUMIFS('DSO FY 20-21'!AZ:AZ,'DSO FY 20-21'!$BC:$BC,SUMMARY!$B21) -> 30468.35 | F21: =IFERROR(C21/(D21/31),0) -> 2.8787093 | G21: =SUMIFS('DSO FY 21-22'!AY:AY,'DSO FY 21-22'!BC:BC,SUMMARY!B21) -> 19351815 | H21: =SUMIFS('DSO FY 21-22'!AZ:AZ,'DSO FY 21-22'!BC:BC,SUMMARY!B21) -> 1.494226e+08 | I21: =SUMIFS('DSO FY 21-22'!BA:BA,'DSO FY 21-22'!BC:BC,SUMMARY!B21) -> 40801.25 | J21: =IFERROR(G21/(H21/31),0) -> 4.0148296 | K21: =SUMIFS('DSO FY 22-23'!AY:AY,'DSO FY 22-23'!BC:BC,SUMMARY!B21) -> 0 | L21: =SUMIFS('DSO FY 22-23'!AZ:AZ,'DSO FY 22-23'!BC:BC,SUMMARY!B21) -> 0 | M21: =SUMIFS('DSO FY 22-23'!BA:BA,'DSO FY 22-23'!BC:BC,SUMMARY!B21) -> 0 | N21: =IFERROR(K21/(L21/31),0) -> 0
B22: SIROHI | C22: =SUMIFS('DSO FY 20-21'!AY:AY,'DSO FY 20-21'!BC:BC,SUMMARY!B22) -> -3227287.6 | D22: =SUMIFS('DSO FY 20-21'!BA:BA,'DSO FY 20-21'!$BC:$BC,SUMMARY!$B22) -> 144547749 | E22: =SUMIFS('DSO FY 20-21'!AZ:AZ,'DSO FY 20-21'!$BC:$BC,SUMMARY!$B22) -> 20634.8 | F22: =IFERROR(C22/(D22/31),0) -> -0.69213057 | G22: =SUMIFS('DSO FY 21-22'!AY:AY,'DSO FY 21-22'!BC:BC,SUMMARY!B22) -> 2399885.7 | H22: =SUMIFS('DSO FY 21-22'!AZ:AZ,'DSO FY 21-22'!BC:BC,SUMMARY!B22) -> 90012276 | I22: =SUMIFS('DSO FY 21-22'!BA:BA,'DSO FY 21-22'!BC:BC,SUMMARY!B22) -> 24441 | J22: =IFERROR(G22/(H22/31),0) -> 0.82651457 | K22: =SUMIFS('DSO FY 22-23'!AY:AY,'DSO FY 22-23'!BC:BC,SUMMARY!B22) -> 0 | L22: =SUMIFS('DSO FY 22-23'!AZ:AZ,'DSO FY 22-23'!BC:BC,SUMMARY!B22) -> 0 | M22: =SUMIFS('DSO FY 22-23'!BA:BA,'DSO FY 22-23'!BC:BC,SUMMARY!B22) -> 0 | N22: =IFERROR(K22/(L22/31),0) -> 0
B23: PALI AO | C23: =SUM(C20:C22) -> 88805451 | D23: =SUM(D20:D22) -> 583724971 | E23: =SUM(E20:E22) -> 83010.5 | F23: =IFERROR(C23/(D23/31),0) -> 4.716209 | G23: =SUM(G20:G22) -> 80888435 | H23: =SUM(H20:H22) -> 421222362 | I23: =SUM(I20:I22) -> 113178.35 | J23: =IFERROR(G23/(H23/31),0) -> 5.9530113 | K23: =SUM(K20:K22) -> 0 | L23: =SUM(L20:L22) -> 0 | M23: =SUM(M20:M22) -> 0 | N23: =IFERROR(K23/(L23/31),0) -> 0
B24: RJ JODHPUR | C24: =SUM(C23,C19,C16) -> 5.0551948e+08 | D24: =SUM(D23,D19,D16) -> 1.8615083e+09 | E24: =SUM(E23,E19,E16) -> 258416 | F24: =IFERROR(C24/(D24/31),0) -> 8.418498 | G24: =SUM(G23,G19,G16) -> 4.8903685e+08 | H24: =SUM(H23,H19,H16) -> 1276371418 | I24: =SUM(I23,I19,I16) -> 330101.8 | J24: =IFERROR(G24/(H24/31),0) -> 11.877532 | K24: =SUM(K23,K19,K16) -> 0 | L24: =SUM(L23,L19,L16) -> 0 | M24: =SUM(M23,M19,M16) -> 0 | N24: =IFERROR(K24/(L24/31),0) -> 0
B25: BIKANER | C25: =SUMIFS('DSO FY 20-21'!AY:AY,'DSO FY 20-21'!BC:BC,SUMMARY!B25) -> 1.1266665e+08 | D25: =SUMIFS('DSO FY 20-21'!BA:BA,'DSO FY 20-21'!$BC:$BC,SUMMARY!$B25) -> 449016240 | E25: =SUMIFS('DSO FY 20-21'!AZ:AZ,'DSO FY 20-21'!$BC:$BC,SUMMARY!$B25) -> 61336.95 | F25: =IFERROR(C25/(D25/31),0) -> 7.7784853 | G25: =SUMIFS('DSO FY 21-22'!AY:AY,'DSO FY 21-22'!BC:BC,SUMMARY!B25) -> 1.0879587e+08 | H25: =SUMIFS('DSO FY 21-22'!AZ:AZ,'DSO FY 21-22'!BC:BC,SUMMARY!B25) -> 326021914 | I25: =SUMIFS('DSO FY 21-22'!BA:BA,'DSO FY 21-22'!BC:BC,SUMMARY!B25) -> 87506.75 | J25: =IFERROR(G25/(H25/31),0) -> 10.344925 | K25: =SUMIFS('DSO FY 22-23'!AY:AY,'DSO FY 22-23'!BC:BC,SUMMARY!B25) -> 0 | L25: =SUMIFS('DSO FY 22-23'!AZ:AZ,'DSO FY 22-23'!BC:BC,SUMMARY!B25) -> 0 | M25: =SUMIFS('DSO FY 22-23'!BA:BA,'DSO FY 22-23'!BC:BC,SUMMARY!B25) -> 0 | N25: =IFERROR(K25/(L25/31),0) -> 0
B26: CHURU | C26: =SUMIFS('DSO FY 20-21'!AY:AY,'DSO FY 20-21'!BC:BC,SUMMARY!B26) -> 38277682 | D26: =SUMIFS('DSO FY 20-21'!BA:BA,'DSO FY 20-21'!$BC:$BC,SUMMARY!$B26) -> 2.2661574e+08 | E26: =SUMIFS('DSO FY 20-21'!AZ:AZ,'DSO FY 20-21'!$BC:$BC,SUMMARY!$B26) -> 30886.85 | F26: =IFERROR(C26/(D26/31),0) -> 5.2362123 | G26: =SUMIFS('DSO FY 21-22'!AY:AY,'DSO FY 21-22'!BC:BC,SUMMARY!B26) -> 35692641 | H26: =SUMIFS('DSO FY 21-22'!AZ:AZ,'DSO FY 21-22'!BC:BC,SUMMARY!B26) -> 1.3441305e+08 | I26: =SUMIFS('DSO FY 21-22'!BA:BA,'DSO FY 21-22'!BC:BC,SUMMARY!B26) -> 36596.65 | J26: =IFERROR(G26/(H26/31),0) -> 8.2318781 | K26: =SUMIFS('DSO FY 22-23'!AY:AY,'DSO FY 22-23'!BC:BC,SUMMARY!B26) -> 0 | L26: =SUMIFS('DSO FY 22-23'!AZ:AZ,'DSO FY 22-23'!BC:BC,SUMMARY!B26) -> 0 | M26: =SUMIFS('DSO FY 22-23'!BA:BA,'DSO FY 22-23'!BC:BC,SUMMARY!B26) -> 0 | N26: =IFERROR(K26/(L26/31),0) -> 0
B27: BIKANER AO | C27: =SUM(C25:C26) -> 1.5094433e+08 | D27: =SUM(D25:D26) -> 6.7563198e+08 | E27: =SUM(E25:E26) -> 92223.8 | F27: =IFERROR(C27/(D27/31),0) -> 6.9257739 | G27: =SUM(G25:G26) -> 1.4448851e+08 | H27: =SUM(H25:H26) -> 4.6043497e+08 | I27: =SUM(I25:I26) -> 124103.4 | J27: =IFERROR(G27/(H27/31),0) -> 9.7280708 | K27: =SUM(K25:K26) -> 0 | L27: =SUM(L25:L26) -> 0 | M27: =SUM(M25:M26) -> 0 | N27: =IFERROR(K27/(L27/31),0) -> 0
B28: JHUNJHUNU | C28: =SUMIFS('DSO FY 20-21'!AY:AY,'DSO FY 20-21'!BC:BC,SUMMARY!B28) -> 32762972 | D28: =SUMIFS('DSO FY 20-21'!BA:BA,'DSO FY 20-21'!$BC:$BC,SUMMARY!$B28) -> 94148967 | E28: =SUMIFS('DSO FY 20-21'!AZ:AZ,'DSO FY 20-21'!$BC:$BC,SUMMARY!$B28) -> 13126.6 | F28: =IFERROR(C28/(D28/31),0) -> 10.787714 | G28: =SUMIFS('DSO FY 21-22'!AY:AY,'DSO FY 21-22'!BC:BC,SUMMARY!B28) -> 44183360 | H28: =SUMIFS('DSO FY 21-22'!AZ:AZ,'DSO FY 21-22'!BC:BC,SUMMARY!B28) -> 88203620 | I28: =SUMIFS('DSO FY 21-22'!BA:BA,'DSO FY 21-22'!BC:BC,SUMMARY!B28) -> 21913.35 | J28: =IFERROR(G28/(H28/31),0) -> 15.528661 | K28: =SUMIFS('DSO FY 22-23'!AY:AY,'DSO FY 22-23'!BC:BC,SUMMARY!B28) -> 0 | L28: =SUMIFS('DSO FY 22-23'!AZ:AZ,'DSO FY 22-23'!BC:BC,SUMMARY!B28) -> 0 | M28: =SUMIFS('DSO FY 22-23'!BA:BA,'DSO FY 22-23'!BC:BC,SUMMARY!B28) -> 0 | N28: =IFERROR(K28/(L28/31),0) -> 0
B29: SIKAR | C29: =SUMIFS('DSO FY 20-21'!AY:AY,'DSO FY 20-21'!BC:BC,SUMMARY!B29) -> 66982156 | D29: =SUMIFS('DSO FY 20-21'!BA:BA,'DSO FY 20-21'!$BC:$BC,SUMMARY!$B29) -> 3.1984659e+08 | E29: =SUMIFS('DSO FY 20-21'!AZ:AZ,'DSO FY 20-21'!$BC:$BC,SUMMARY!$B29) -> 45780.2 | F29: =IFERROR(C29/(D29/31),0) -> 6.4920085 | G29: =SUMIFS('DSO FY 21-22'!AY:AY,'DSO FY 21-22'!BC:BC,SUMMARY!B29) -> 71406348 | H29: =SUMIFS('DSO FY 21-22'!AZ:AZ,'DSO FY 21-22'!BC:BC,SUMMARY!B29) -> 2.403737e+08 | I29: =SUMIFS('DSO FY 21-22'!BA:BA,'DSO FY 21-22'!BC:BC,SUMMARY!B29) -> 63271.55 | J29: =IFERROR(G29/(H29/31),0) -> 9.2089806 | K29: =SUMIFS('DSO FY 22-23'!AY:AY,'DSO FY 22-23'!BC:BC,SUMMARY!B29) -> 0 | L29: =SUMIFS('DSO FY 22-23'!AZ:AZ,'DSO FY 22-23'!BC:BC,SUMMARY!B29) -> 0 | M29: =SUMIFS('DSO FY 22-23'!BA:BA,'DSO FY 22-23'!BC:BC,SUMMARY!B29) -> 0 | N29: =IFERROR(K29/(L29/31),0) -> 0
B30: SIKAR AO | C30: =SUM(C28:C29) -> 99745128 | D30: =SUM(D28:D29) -> 4.1399556e+08 | E30: =SUM(E28:E29) -> 58906.8 | F30: =IFERROR(C30/(D30/31),0) -> 7.4689181 | G30: =SUM(G28:G29) -> 1.1558971e+08 | H30: =SUM(H28:H29) -> 328577323 | I30: =SUM(I28:I29) -> 85184.9 | J30: =IFERROR(G30/(H30/31),0) -> 10.905442 | K30: =SUM(K28:K29) -> 0 | L30: =SUM(L28:L29) -> 0 | M30: =SUM(M28:M29) -> 0 | N30: =IFERROR(K30/(L30/31),0) -> 0
B31: HANUMANGARH | C31: =SUMIFS('DSO FY 20-21'!AY:AY,'DSO FY 20-21'!BC:BC,SUMMARY!B31) -> 42519847 | D31: =SUMIFS('DSO FY 20-21'!BA:BA,'DSO FY 20-21'!$BC:$BC,SUMMARY!$B31) -> 403749682 | E31: =SUMIFS('DSO FY 20-21'!AZ:AZ,'DSO FY 20-21'!$BC:$BC,SUMMARY!$B31) -> 55071.3 | F31: =IFERROR(C31/(D31/31),0) -> 3.2646843 | G31: =SUMIFS('DSO FY 21-22'!AY:AY,'DSO FY 21-22'!BC:BC,SUMMARY!B31) -> 54676335 | H31: =SUMIFS('DSO FY 21-22'!AZ:AZ,'DSO FY 21-22'!BC:BC,SUMMARY!B31) -> 279887478 | I31: =SUMIFS('DSO FY 21-22'!BA:BA,'DSO FY 21-22'!BC:BC,SUMMARY!B31) -> 74547.75 | J31: =IFERROR(G31/(H31/31),0) -> 6.055885 | K31: =SUMIFS('DSO FY 22-23'!AY:AY,'DSO FY 22-23'!BC:BC,SUMMARY!B31) -> 0 | L31: =SUMIFS('DSO FY 22-23'!AZ:AZ,'DSO FY 22-23'!BC:BC,SUMMARY!B31) -> 0 | M31: =SUMIFS('DSO FY 22-23'!BA:BA,'DSO FY 22-23'!BC:BC,SUMMARY!B31) -> 0 | N31: =IFERROR(K31/(L31/31),0) -> 0
B32: SRI GANGANAGAR | C32: =SUMIFS('DSO FY 20-21'!AY:AY,'DSO FY 20-21'!BC:BC,SUMMARY!B32) -> 8182257.1 | D32: =SUMIFS('DSO FY 20-21'!BA:BA,'DSO FY 20-21'!$BC:$BC,SUMMARY!$B32) -> 5.3921013e+08 | E32: =SUMIFS('DSO FY 20-21'!AZ:AZ,'DSO FY 20-21'!$BC:$BC,SUMMARY!$B32) -> 73628.55 | F32: =IFERROR(C32/(D32/31),0) -> 0.47041024 | G32: =SUMIFS('DSO FY 21-22'!AY:AY,'DSO FY 21-22'!BC:BC,SUMMARY!B32) -> 26526434 | H32: =SUMIFS('DSO FY 21-22'!AZ:AZ,'DSO FY 21-22'!BC:BC,SUMMARY!B32) -> 375862324 | I32: =SUMIFS('DSO FY 21-22'!BA:BA,'DSO FY 21-22'!BC:BC,SUMMARY!B32) -> 91997.95 | J32: =IFERROR(G32/(H32/31),0) -> 2.1878209 | K32: =SUMIFS('DSO FY 22-23'!AY:AY,'DSO FY 22-23'!BC:BC,SUMMARY!B32) -> 0 | L32: =SUMIFS('DSO FY 22-23'!AZ:AZ,'DSO FY 22-23'!BC:BC,SUMMARY!B32) -> 0 | M32: =SUMIFS('DSO FY 22-23'!BA:BA,'DSO FY 22-23'!BC:BC,SUMMARY!B32) -> 0 | N32: =IFERROR(K32/(L32/31),0) -> 0
B33: SGNR AO | C33: =SUM(C31:C32) -> 50702104 | D33: =SUM(D31:D32) -> 9.4295981e+08 | E33: =SUM(E31:E32) -> 128699.85 | F33: =IFERROR(C33/(D33/31),0) -> 1.6668422 | G33: =SUM(G31:G32) -> 81202769 | H33: =SUM(H31:H32) -> 655749802 | I33: =SUM(I31:I32) -> 166545.7 | J33: =IFERROR(G33/(H33/31),0) -> 3.8387901 | K33: =SUM(K31:K32) -> 0 | L33: =SUM(L31:L32) -> 0 | M33: =SUM(M31:M32) -> 0 | N33: =IFERROR(K33/(L33/31),0) -> 0
B34: RJ-SGNR | C34: =SUM(C33,C30,C27) -> 3.0139157e+08 | D34: =SUM(D33,D30,D27) -> 2.0325874e+09 | E34: =SUM(E33,E30,E27) -> 279830.45 | F34: =IFERROR(C34/(D34/31),0) -> 4.5966726 | G34: =SUM(G33,G30,G27) -> 3.4128099e+08 | H34: =SUM(H33,H30,H27) -> 1.4447621e+09 | I34: =SUM(I33,I30,I27) -> 375834 | J34: =IFERROR(G34/(H34/31),0) -> 7.3228048 | K34: =SUM(K33,K30,K27) -> 0 | L34: =SUM(L33,L30,L27) -> 0 | M34: =SUM(M33,M30,M27) -> 0 | N34: =IFERROR(K34/(L34/31),0) -> 0
B35: West-1-A | C35: =SUM(C34,C24,C13) -> 1.070058e+09 | D35: =SUM(D34,D24,D13) -> 5669652182 | E35: =SUM(E34,E24,E13) -> 788143.4 | F35: =IFERROR(C35/(D35/31),0) -> 5.8507641 | G35: =SUM(G34,G24,G13) -> 1.0796677e+09 | H35: =SUM(H34,H24,H13) -> 4.1127262e+09 | I35: =SUM(I34,I24,I13) -> 1084565.4 | J35: =IFERROR(G35/(H35/31),0) -> 8.1380807 | K35: =SUM(K34,K24,K13) -> 5.3695032e+08 | L35: =SUM(L34,L24,L13) -> 2786762384 | M35: =SUM(M34,M24,M13) -> 377777.4 | N35: =IFERROR(K35/(L35/31),0) -> 5.9730461
B36: BHILWARA | C36: =SUMIFS('DSO FY 20-21'!AY:AY,'DSO FY 20-21'!BC:BC,SUMMARY!B36) -> 32916988 | D36: =SUMIFS('DSO FY 20-21'!BA:BA,'DSO FY 20-21'!$BC:$BC,SUMMARY!$B36) -> 222592247 | E36: =SUMIFS('DSO FY 20-21'!AZ:AZ,'DSO FY 20-21'!$BC:$BC,SUMMARY!$B36) -> 31901.9 | F36: =IFERROR(C36/(D36/31),0) -> 4.5842865 | G36: =SUMIFS('DSO FY 21-22'!AY:AY,'DSO FY 21-22'!BC:BC,SUMMARY!B36) -> 32484167 | H36: =SUMIFS('DSO FY 21-22'!AZ:AZ,'DSO FY 21-22'!BC:BC,SUMMARY!B36) -> 178384713 | I36: =SUMIFS('DSO FY 21-22'!BA:BA,'DSO FY 21-22'!BC:BC,SUMMARY!B36) -> 46518 | J36: =IFERROR(G36/(H36/31),0) -> 5.6451541 | K36: =SUMIFS('DSO FY 22-23'!AY:AY,'DSO FY 22-23'!BC:BC,SUMMARY!B36) -> 0 | L36: =SUMIFS('DSO FY 22-23'!AZ:AZ,'DSO FY 22-23'!BC:BC,SUMMARY!B36) -> 0 | M36: =SUMIFS('DSO FY 22-23'!BA:BA,'DSO FY 22-23'!BC:BC,SUMMARY!B36) -> 0 | N36: =IFERROR(K36/(L36/31),0) -> 0
B37: CHITTORGARH | C37: =SUMIFS('DSO FY 20-21'!AY:AY,'DSO FY 20-21'!BC:BC,SUMMARY!B37) -> 59242248 | D37: =SUMIFS('DSO FY 20-21'!BA:BA,'DSO FY 20-21'!$BC:$BC,SUMMARY!$B37) -> 3.8185607e+08 | E37: =SUMIFS('DSO FY 20-21'!AZ:AZ,'DSO FY 20-21'!$BC:$BC,SUMMARY!$B37) -> 53830.45 | F37: =IFERROR(C37/(D37/31),0) -> 4.809429 | G37: =SUMIFS('DSO FY 21-22'!AY:AY,'DSO FY 21-22'!BC:BC,SUMMARY!B37) -> 47075989 | H37: =SUMIFS('DSO FY 21-22'!AZ:AZ,'DSO FY 21-22'!BC:BC,SUMMARY!B37) -> 2.6454658e+08 | I37: =SUMIFS('DSO FY 21-22'!BA:BA,'DSO FY 21-22'!BC:BC,SUMMARY!B37) -> 73205.8 | J37: =IFERROR(G37/(H37/31),0) -> 5.5164413 | K37: =SUMIFS('DSO FY 22-23'!AY:AY,'DSO FY 22-23'!BC:BC,SUMMARY!B37) -> 0 | L37: =SUMIFS('DSO FY 22-23'!AZ:AZ,'DSO FY 22-23'!BC:BC,SUMMARY!B37) -> 0 | M37: =SUMIFS('DSO FY 22-23'!BA:BA,'DSO FY 22-23'!BC:BC,SUMMARY!B37) -> 0 | N37: =IFERROR(K37/(L37/31),0) -> 0
B38: PRATAPGARH | C38: =SUMIFS('DSO FY 20-21'!AY:AY,'DSO FY 20-21'!BC:BC,SUMMARY!B38) -> 24004514 | D38: =SUMIFS('DSO FY 20-21'!BA:BA,'DSO FY 20-21'!$BC:$BC,SUMMARY!$B38) -> 173003794 | E38: =SUMIFS('DSO FY 20-21'!AZ:AZ,'DSO FY 20-21'!$BC:$BC,SUMMARY!$B38) -> 25147.9 | F38: =IFERROR(C38/(D38/31),0) -> 4.3012927 | G38: =SUMIFS('DSO FY 21-22'!AY:AY,'DSO FY 21-22'!BC:BC,SUMMARY!B38) -> 22419813 | H38: =SUMIFS('DSO FY 21-22'!AZ:AZ,'DSO FY 21-22'!BC:BC,SUMMARY!B38) -> 96230896 | I38: =SUMIFS('DSO FY 21-22'!BA:BA,'DSO FY 21-22'!BC:BC,SUMMARY!B38) -> 27903.25 | J38: =IFERROR(G38/(H38/31),0) -> 7.2223602 | K38: =SUMIFS('DSO FY 22-23'!AY:AY,'DSO FY 22-23'!BC:BC,SUMMARY!B38) -> 0 | L38: =SUMIFS('DSO FY 22-23'!AZ:AZ,'DSO FY 22-23'!BC:BC,SUMMARY!B38) -> 0 | M38: =SUMIFS('DSO FY 22-23'!BA:BA,'DSO FY 22-23'!BC:BC,SUMMARY!B38) -> 0 | N38: =IFERROR(K38/(L38/31),0) -> 0
B39: BHILWARA AO | C39: =SUM(C36:C38) -> 1.1616375e+08 | D39: =SUM(D36:D38) -> 7.7745211e+08 | E39: =SUM(E36:E38) -> 110880.25 | F39: 4.6318946 | G39: =SUM(G36:G38) -> 1.0197997e+08 | H39: =SUM(H36:H38) -> 539162186 | I39: =SUM(I36:I38) -> 147627.05 | J39: 5.4803252 | K39: =SUM(K36:K38) -> 0 | L39: =SUM(L36:L38) -> 0 | M39: =SUM(M36:M38) -> 0 | N39: 5.3006891
B40: BANSWARA | C40: =SUMIFS('DSO FY 20-21'!AY:AY,'DSO FY 20-21'!BC:BC,SUMMARY!B40) -> 63171998 | D40: =SUMIFS('DSO FY 20-21'!BA:BA,'DSO FY 20-21'!$BC:$BC,SUMMARY!$B40) -> 3.4309419e+08 | E40: =SUMIFS('DSO FY 20-21'!AZ:AZ,'DSO FY 20-21'!$BC:$BC,SUMMARY!$B40) -> 49489.05 | F40: =IFERROR(C40/(D40/31),0) -> 5.7078552 | G40: =SUMIFS('DSO FY 21-22'!AY:AY,'DSO FY 21-22'!BC:BC,SUMMARY!B40) -> 38582222 | H40: =SUMIFS('DSO FY 21-22'!AZ:AZ,'DSO FY 21-22'!BC:BC,SUMMARY!B40) -> 210908585 | I40: =SUMIFS('DSO FY 21-22'!BA:BA,'DSO FY 21-22'!BC:BC,SUMMARY!B40) -> 58809.5 | J40: =IFERROR(G40/(H40/31),0) -> 5.670935 | K40: =SUMIFS('DSO FY 22-23'!AY:AY,'DSO FY 22-23'!BC:BC,SUMMARY!B40) -> 0 | L40: =SUMIFS('DSO FY 22-23'!AZ:AZ,'DSO FY 22-23'!BC:BC,SUMMARY!B40) -> 0 | M40: =SUMIFS('DSO FY 22-23'!BA:BA,'DSO FY 22-23'!BC:BC,SUMMARY!B40) -> 0 | N40: =IFERROR(K40/(L40/31),0) -> 0
B41: DUNGARPUR | C41: =SUMIFS('DSO FY 20-21'!AY:AY,'DSO FY 20-21'!BC:BC,SUMMARY!B41) -> 83158749 | D41: =SUMIFS('DSO FY 20-21'!BA:BA,'DSO FY 20-21'!$BC:$BC,SUMMARY!$B41) -> 4.3402891e+08 | E41: =SUMIFS('DSO FY 20-21'!AZ:AZ,'DSO FY 20-21'!$BC:$BC,SUMMARY!$B41) -> 62404.25 | F41: =IFERROR(C41/(D41/31),0) -> 5.939515 | G41: =SUMIFS('DSO FY 21-22'!AY:AY,'DSO FY 21-22'!BC:BC,SUMMARY!B41) -> 71364259 | H41: =SUMIFS('DSO FY 21-22'!AZ:AZ,'DSO FY 21-22'!BC:BC,SUMMARY!B41) -> 2.611563e+08 | I41: =SUMIFS('DSO FY 21-22'!BA:BA,'DSO FY 21-22'!BC:BC,SUMMARY!B41) -> 73764.25 | J41: =IFERROR(G41/(H41/31),0) -> 8.4711416 | K41: =SUMIFS('DSO FY 22-23'!AY:AY,'DSO FY 22-23'!BC:BC,SUMMARY!B41) -> 0 | L41: =SUMIFS('DSO FY 22-23'!AZ:AZ,'DSO FY 22-23'!BC:BC,SUMMARY!B41) -> 0 | M41: =SUMIFS('DSO FY 22-23'!BA:BA,'DSO FY 22-23'!BC:BC,SUMMARY!B41) -> 0 | N41: =IFERROR(K41/(L41/31),0) -> 0
...

Sheet DSO FY 20-21
C1: Apr'20 | G1: May'20 | K1: Jun'20 | O1: July'20 | S1: Aug'20 | W1: Sep'20 | AA1: Oct'20 | AE1: Nov'20 | AI1: Dec'20 | AM1: Jan'21 | AQ1: Feb'21 | AU1: Mar'21 | AY1: Avg. DSO (May 20-Mar 21)
A2: SOLD TO PARTY | B2: CUSTOMER DESCRIPTION | C2: Apr'20 | D2: Sale | E2: Billing Value (Apr'20) | F2: DSO | G2: May'20 | H2: Sale | I2: Billing value (May'20) | J2: DSO | K2: Jun'20 | L2: Jun'20 | M2: Billing value (Jun'20) | N2: DSO | O2: July'20 | P2: July'20 | Q2: Billing value (Jul'20) | R2: DSO | S2: Aug'20 | T2: Aug'20 | U2: Billing value (Aug'20) | V2: DSO | W2: Sep'20 | X2: Sep'20 | Y2: Billing value (Sep'20) | Z2: DSO | AA2: Oct'20 | AB2: Oct'20 | AC2: Billing value (Oct'20) | AD2: DSO | AE2: Nov'20 | AF2: Nov'20 | AG2: Billing value (Nov'20) | AH2: DSO | AI2: Dec'20 | AJ2: Dec'20 | AK2: Billing value (Dec'20) | AL2: DSO | AM2: Jan'21 | AN2: Jan'21 | AO2: Billing value (Jan'21) | AP2: DSO | AQ2: Feb'21 | AR2: Feb'21 | AS2: Billing value (Feb'21) | AT2: DSO | AU2: Mar'21 | AV2: Mar'21 | AW2: Billing value (Mar'21) | AX2: DSO | AY2: Total O/S | AZ2: Total Sale | BA2: Total Billing Value | BB2: Avg. DSO | BC2: District | BD2: AO | BE2: Stat
A3: 119043 | B3: AJAY TRADERS | C3: -209165.29 | D3: 0 | E3: 0 | F3: =IFERROR(C3/(E3/30),0) -> 0 | G3: -282465.29 | H3: 45 | I3: 338400 | J3: =IFERROR(G3/(I3/31),0) -> -25.875957 | K3: -286065.29 | L3: 0 | M3: 0 | N3: =IFERROR(K3/(M3/30),0) -> 0 | O3: -142265.29 | P3: 20 | Q3: 149400 | R3: =IFERROR(O3/(Q3/31),0) -> -29.519572 | S3: 167934.71 | T3: 102 | U3: 754840 | V3: =IFERROR(S3/(U3/31),0) -> 6.896794 | W3: -99310.08 | X3: 96 | Y3: 703220 | Z3: =IFERROR(W3/(Y3/30),0) -> -4.2366577 | AA3: -107715.08 | AB3: 51.5 | AC3: 378780 | AD3: =IFERROR(AA3/(AC3/31),0) -> -8.8155855 | AE3: -102160.66 | AF3: 42 | AG3: 328440 | AH3: =IFERROR(AE3/(AG3/30),0) -> -9.331445 | AI3: 134134.34 | AJ3: 78.5 | AK3: 564230 | AL3: =IFERROR(AI3/(AK3/31),0) -> 7.3696268 | AM3: 234199.34 | AN3: 117 | AO3: 839940 | AP3: =IFERROR(AM3/(AO3/31),0) -> 8.6436883 | AQ3: -55060.65 | AR3: 115 | AS3: 815400 | AT3: =IFERROR(AQ3/(AS3/28),0) -> -1.8907263 | AU3: 246319.33 | AV3: 130 | AW3: 993800 | AX3: =IFERROR(AU3/(AW3/31),0) -> 7.6835372 | AY3: =G3+K3+O3+S3+W3+AA3+AE3+AI3+AM3+AQ3+AU3 -> -292454.62 | AZ3: =H3+L3+P3+T3+X3+AB3+AF3+AJ3+AN3+AR3+AV3 -> 797 | BA3: =I3+M3+Q3+U3+Y3+AC3+AG3+AK3+AO3+AS3+AW3 -> 5866450 | BB3: =IFERROR(AY3/(BA3/31),0) -> -1.5454139 | BC3: ALWAR | BD3: ALWAR | BE3: RJ-JAIPUR
A4: 119046 | B4: GARG AGRO AGENCIES | C4: 288530.47 | D4: 124.5 | E4: 936550 | F4: =IFERROR(C4/(E4/30),0) -> 9.2423406 | G4: -287894.53 | H4: 832 | I4: 5996100 | J4: =IFERROR(G4/(I4/31),0) -> -1.4884225 | K4: -357044.53 | L4: 661 | M4: 4779650 | N4: =IFERROR(K4/(M4/30),0) -> -2.2410293 | O4: -655947.84 | P4: 605 | Q4: 4323900 | R4: =IFERROR(O4/(Q4/31),0) -> -4.7027875 | S4: 17309.16 | T4: 554 | U4: 3979500 | V4: =IFERROR(S4/(U4/31),0) -> 0.13483703 | W4: -345070.89 | X4: 385 | Y4: 2686100 | Z4: =IFERROR(W4/(Y4/30),0) -> -3.8539618 | AA4: -632154.89 | AB4: 603.5 | AC4: 4471950 | AD4: =IFERROR(AA4/(AC4/31),0) -> -4.3821603 | AE4: 63169.77 | AF4: 567.5 | AG4: 4230110 | AH4: =IFERROR(AE4/(AG4/30),0) -> 0.4480009 | AI4: -375080.23 | AJ4: 404.5 | AK4: 2847690 | AL4: =IFERROR(AI4/(AK4/31),0) -> -4.0831295 | AM4: 92167.88 | AN4: 508 | AO4: 3545200 | AP4: =IFERROR(AM4/(AO4/31),0) -> 0.80593599 | AQ4: -233283.15 | AR4: 536.5 | AS4: 3839750 | AT4: =IFERROR(AQ4/(AS4/28),0) -> -1.7011337 | AU4: -501810.17 | AV4: 651 | AW4: 4677790 | AX4: =IFERROR(AU4/(AW4/31),0) -> -3.3255266 | AY4: =G4+K4+O4+S4+W4+AA4+AE4+AI4+AM4+AQ4+AU4 -> -3215639.4 | AZ4: =H4+L4+P4+T4+X4+AB4+AF4+AJ4+AN4+AR4+AV4 -> 6308 | BA4: =I4+M4+Q4+U4+Y4+AC4+AG4+AK4+AO4+AS4+AW4 -> 45377740 | BB4: =IFERROR(AY4/(BA4/31),0) -> -2.196778 | BC4: ALWAR | BD4: ALWAR | BE4: RJ-JAIPUR
A5: 122712 | B5: RAJ BUILDING MATERIAL | C5: 0 | D5: 45 | E5: 315900 | F5: =IFERROR(C5/(E5/30),0) -> 0 | G5: 0 | H5: 0 | I5: 0 | J5: =IFERROR(G5/(I5/31),0) -> 0 | K5: 226689.93 | L5: 35 | M5: 248500 | N5: =IFERROR(K5/(M5/30),0) -> 27.366994 | O5: -17210.07 | P5: 42 | Q5: 294840 | R5: =IFERROR(O5/(Q5/31),0) -> -1.8094973 | S5: -15385.07 | T5: 41.5 | U5: 287180 | V5: =IFERROR(S5/(U5/31),0) -> -1.6607604 | W5: -9545.07 | X5: 26.5 | Y5: 180730 | Z5: =IFERROR(W5/(Y5/30),0) -> -1.5844193 | AA5: -2100.07 | AB5: 7.5 | AC5: 54525 | AD5: =IFERROR(AA5/(AC5/31),0) -> -1.1939875 | AE5: -18224.73 | AF5: 49.5 | AG5: 362715 | AH5: =IFERROR(AE5/(AG5/30),0) -> -1.5073595 | AI5: 71705.27 | AJ5: 22.5 | AK5: 152325 | AL5: =IFERROR(AI5/(AK5/31),0) -> 14.592899 | AM5: -20579.73 | AN5: 42 | AO5: 286440 | AP5: =IFERROR(AM5/(AO5/31),0) -> -2.2272435 | AQ5: -2049.73 | AR5: 5 | AS5: 34850 | AT5: =IFERROR(AQ5/(AS5/28),0) -> -1.6468419 | AU5: 246790.27 | AV5: 42 | AW5: 291480 | AX5: =IFERROR(AU5/(AW5/31),0) -> 26.247078 | AY5: =G5+K5+O5+S5+W5+AA5+AE5+AI5+AM5+AQ5+AU5 -> 460091 | AZ5: =H5+L5+P5+T5+X5+AB5+AF5+AJ5+AN5+AR5+AV5 -> 313.5 | BA5: =I5+M5+Q5+U5+Y5+AC5+AG5+AK5+AO5+AS5+AW5 -> 2193585 | BB5: =IFERROR(AY5/(BA5/31),0) -> 6.5020599 | BC5: ALWAR | BD5: ALWAR | BE5: RJ-JAIPUR
A6: 140481 | B6: Goyal & Co. | C6: -27705.76 | D6: 100 | E6: 732000 | F6: =IFERROR(C6/(E6/30),0) -> -1.135482 | G6: -197863.28 | H6: 485.3 | I6: 3540096 | J6: =IFERROR(G6/(I6/31),0) -> -1.7326541 | K6: 243418.72 | L6: 466 | M6: 3410720 | N6: =IFERROR(K6/(M6/30),0) -> 2.1410616 | O6: 1134388.6 | P6: 416.9 | Q6: 3026673 | R6: =IFERROR(O6/(Q6/31),0) -> 11.618713 | S6: 1673626.6 | T6: 302.55 | U6: 2202073.5 | V6: =IFERROR(S6/(U6/31),0) -> 23.560714 | W6: 1555757.1 | X6: 332.5 | Y6: 2363865 | Z6: =IFERROR(W6/(Y6/30),0) -> 19.744238 | AA6: 1467331.1 | AB6: 375 | AC6: 2796050 | AD6: =IFERROR(AA6/(AC6/31),0) -> 16.268401 | AE6: 1533499.8 | AF6: 335.5 | AG6: 2567210 | AH6: =IFERROR(AE6/(AG6/30),0) -> 17.92023 | AI6: 1336299.8 | AJ6: 435 | AK6: 3128050 | AL6: =IFERROR(AI6/(AK6/31),0) -> 13.243168 | AM6: 1420819.7 | AN6: 288 | AO6: 2070310 | AP6: =IFERROR(AM6/(AO6/31),0) -> 21.27479 | AQ6: 1719882.7 | AR6: 358 | AS6: 2611710 | AT6: =IFERROR(AQ6/(AS6/28),0) -> 18.438768 | AU6: 1859526.6 | AV6: 423 | AW6: 3056840 | AX6: =IFERROR(AU6/(AW6/31),0) -> 18.857815 | AY6: =G6+K6+O6+S6+W6+AA6+AE6+AI6+AM6+AQ6+AU6 -> 13746687 | AZ6: =H6+L6+P6+T6+X6+AB6+AF6+AJ6+AN6+AR6+AV6 -> 4217.75 | BA6: =I6+M6+Q6+U6+Y6+AC6+AG6+AK6+AO6+AS6+AW6 -> 30773598 | BB6: =IFERROR(AY6/(BA6/31),0) -> 13.847822 | BC6: ALWAR | BD6: ALWAR | BE6: RJ-JAIPUR
A7: 140927 | B7: SHIV CHARAN LAL RAKESH KUMAR | C7: -6752.19 | D7: 51.5 | E7: 366205 | F7: =IFERROR(C7/(E7/30),0) -> -0.55314837 | G7: 173640.31 | H7: 150.75 | I7: 1083877.5 | J7: =IFERROR(G7/(I7/31),0) -> 4.9662896 | K7: -23014.69 | L7: 102 | M7: 740365 | N7: =IFERROR(K7/(M7/30),0) -> -0.93256799 | O7: 49856.83 | P7: 151 | Q7: 1074720 | R7: =IFERROR(O7/(Q7/31),0) -> 1.4381064 | S7: 143046.83 | T7: 150 | U7: 1075250 | V7: =IFERROR(S7/(U7/31),0) -> 4.1241123 | W7: 58775.43 | X7: 177.1 | Y7: 1260502 | Z7: =IFERROR(W7/(Y7/30),0) -> 1.3988577 | AA7: 231235.94 | AB7: 217 | AC7: 1586115 | AD7: =IFERROR(AA7/(AC7/31),0) -> 4.5194164 | AE7: 182966.97 | AF7: 176.95 | AG7: 1338471.5 | AH7: =IFERROR(AE7/(AG7/30),0) -> 4.1009533 | AI7: -13942.03 | AJ7: 265.5 | AK7: 1868935 | AL7: =IFERROR(AI7/(AK7/31),0) -> -0.23125627 | AM7: 59630.93 | AN7: 278.5 | AO7: 1959020 | AP7: =IFERROR(AM7/(AO7/31),0) -> 0.94361407 | AQ7: 207137.43 | AR7: 329.25 | AS7: 2360447.5 | AT7: =IFERROR(AQ7/(AS7/28),0) -> 2.4570968 | AU7: 145951.74 | AV7: 355.4 | AW7: 2597976 | AX7: =IFERROR(AU7/(AW7/31),0) -> 1.7415496 | AY7: =G7+K7+O7+S7+W7+AA7+AE7+AI7+AM7+AQ7+AU7 -> 1215285.7 | AZ7: =H7+L7+P7+T7+X7+AB7+AF7+AJ7+AN7+AR7+AV7 -> 2353.45 | BA7: =I7+M7+Q7+U7+Y7+AC7+AG7+AK7+AO7+AS7+AW7 -> 16945680 | BB7: =IFERROR(AY7/(BA7/31),0) -> 2.2232131 | BC7: ALWAR | BD7: ALWAR | BE7: RJ-JAIPUR
A8: 141581 | B8: GUPTA KHAD BEEJ BHANDAR | C8: -1699.96 | D8: 20 | E8: 146600 | F8: =IFERROR(C8/(E8/30),0) -> -0.34787722 | G8: -19203.36 | H8: 87 | I8: 637040 | J8: =IFERROR(G8/(I8/31),0) -> -0.93448474 | K8: -34115.36 | L8: 87.5 | M8: 636050 | N8: =IFERROR(K8/(M8/30),0) -> -1.6090886 | O8: 150697.68 | P8: 71.5 | Q8: 502280 | R8: =IFERROR(O8/(Q8/31),0) -> 9.3008443 | S8: -18935.32 | T8: 56.5 | U8: 416730 | V8: =IFERROR(S8/(U8/31),0) -> -1.4085737 | W8: 63679.68 | X8: 53 | Y8: 382310 | Z8: =IFERROR(W8/(Y8/30),0) -> 4.9969669 | AA8: 123399.68 | AB8: 60 | AC8: 442050 | AD8: =IFERROR(AA8/(AC8/31),0) -> 8.6537498 | AE8: 52749.84 | AF8: 55 | AG8: 416600 | AH8: =IFERROR(AE8/(AG8/30),0) -> 3.7985963 | AI8: -27250.16 | AJ8: 63.5 | AK8: 447720 | AL8: =IFERROR(AI8/(AK8/31),0) -> -1.886793 | AM8: -46120.16 | AN8: 74 | AO8: 525440 | AP8: =IFERROR(AM8/(AO8/31),0) -> -2.7210052 | AQ8: 80114.84 | AR8: 94.5 | AS8: 678440 | AT8: =IFERROR(AQ8/(AS8/28),0) -> 3.3064317 | AU8: 7028.34 | AV8: 57 | AW8: 406780 | AX8: =IFERROR(AU8/(AW8/31),0) -> 0.53561763 | AY8: =G8+K8+O8+S8+W8+AA8+AE8+AI8+AM8+AQ8+AU8 -> 332045.7 | AZ8: =H8+L8+P8+T8+X8+AB8+AF8+AJ8+AN8+AR8+AV8 -> 759.5 | BA8: =I8+M8+Q8+U8+Y8+AC8+AG8+AK8+AO8+AS8+AW8 -> 5491440 | BB8: =IFERROR(AY8/(BA8/31),0) -> 1.8744476 | BC8: ALWAR | BD8: ALWAR | BE8: RJ-JAIPUR
A9: 142759 | B9: GUPTA AGENCIES | C9: -8195.34 | D9: 61.5 | E9: 459680 | F9: =IFERROR(C9/(E9/30),0) -> -0.53485077 | G9: -29720.34 | H9: 110.5 | I9: 828960 | J9: =IFERROR(G9/(I9/31),0) -> -1.1114294 | K9: 44619.66 | L9: 50 | M9: 371900 | N9: =IFERROR(K9/(M9/30),0) -> 3.5993272 | O9: -25886.77 | P9: 63 | Q9: 468360 | R9: =IFERROR(O9/(Q9/31),0) -> -1.7134039 | S9: 267729.23 | T9: 71 | U9: 521320 | V9: =IFERROR(S9/(U9/31),0) -> 15.920368 | W9: 29299.23 | X9: 10 | Y9: 73100 | Z9: =IFERROR(W9/(Y9/30),0) -> 12.024308 | AA9: 53719.23 | AB9: 50 | AC9: 372600 | AD9: =IFERROR(AA9/(AC9/31),0) -> 4.4693938 | AE9: 154464.29 | AF9: 53.5 | AG9: 409470 | AH9: =IFERROR(AE9/(AG9/30),0) -> 11.316894 | AI9: -35040.71 | AJ9: 50 | AK9: 357700 | AL9: =IFERROR(AI9/(AK9/31),0) -> -3.0367962 | AM9: -6090.7 | AN9: 10 | AO9: 68000 | AP9: =IFERROR(AM9/(AO9/31),0) -> -2.7766426 | AQ9: -19370.7 | AR9: 51 | AS9: 375820 | AT9: =IFERROR(AQ9/(AS9/28),0) -> -1.4431898 | AU9: 238199.3 | AV9: 53 | AW9: 395630 | AX9: =IFERROR(AU9/(AW9/31),0) -> 18.664354 | AY9: =G9+K9+O9+S9+W9+AA9+AE9+AI9+AM9+AQ9+AU9 -> 671921.72 | AZ9: =H9+L9+P9+T9+X9+AB9+AF9+AJ9+AN9+AR9+AV9 -> 572 | BA9: =I9+M9+Q9+U9+Y9+AC9+AG9+AK9+AO9+AS9+AW9 -> 4242860 | BB9: =IFERROR(AY9/(BA9/31),0) -> 4.9093237 | BC9: ALWAR | BD9: ALWAR | BE9: RJ-JAIPUR
A10: 142984 | B10: JAGDAMBEY BUILDING MATERIAL SU | C10: -9280.34 | D10: 74.5 | E10: 561200 | F10: =IFERROR(C10/(E10/30),0) -> -0.496098 | G10: -37142.44 | H10: 181 | I10: 1333580 | J10: =IFERROR(G10/(I10/31),0) -> -0.863402 | K10: 300587.06 | L10: 167.75 | M10: 1235392.5 | N10: =IFERROR(K10/(M10/30),0) -> 7.2993901 | O10: 137583.76 | P10: 107.5 | Q10: 785800 | R10: =IFERROR(O10/(Q10/31),0) -> 5.4277126 | S10: 99850.36 | T10: 79.05 | U10: 584758.5 | V10: =IFERROR(S10/(U10/31),0) -> 5.2934009 | W10: 570315.84 | X10: 109.2 | Y10: 778344 | Z10: =IFERROR(W10/(Y10/30),0) -> 21.981894 | AA10: 577857.84 | AB10: 139.7 | AC10: 1044519 | AD10: =IFERROR(AA10/(AC10/31),0) -> 17.150088 | AE10: 514425.76 | AF10: 71.5 | AG10: 537480 | AH10: =IFERROR(AE10/(AG10/30),0) -> 28.713204 | AI10: 209554.76 | AJ10: 107 | AK10: 774490 | AL10: =IFERROR(AI10/(AK10/31),0) -> 8.3877101 | AM10: 510271.75 | AN10: 95 | AO10: 664800 | AP10: =IFERROR(AM10/(AO10/31),0) -> 23.79426 | AQ10: 637576.76 | AR10: 96 | AS10: 696645 | AT10: =IFERROR(AQ10/(AS10/28),0) -> 25.625892 | AU10: 572107.73 | AV10: 114 | AW10: 834580 | AX10: =IFERROR(AU10/(AW10/31),0) -> 21.250617 | AY10: =G10+K10+O10+S10+W10+AA10+AE10+AI10+AM10+AQ10+AU10 -> 4092989.2 | AZ10: =H10+L10+P10+T10+X10+AB10+AF10+AJ10+AN10+AR10+AV10 -> 1267.7 | BA10: =I10+M10+Q10+U10+Y10+AC10+AG10+AK10+AO10+AS10+AW10 -> 9270389 | BB10: =IFERROR(AY10/(BA10/31),0) -> 13.686876 | BC10: ALWAR | BD10: ALWAR | BE10: RJ-JAIPUR
A11: 143509 | B11: PAWAN BUILDERS | C11: -17922.47 | D11: 25 | E11: 195250 | F11: =IFERROR(C11/(E11/30),0) -> -2.7537726 | G11: 322116.9 | H11: 200.65 | I11: 1415020.5 | J11: =IFERROR(G11/(I11/31),0) -> 7.0568758 | K11: 324511.9 | L11: 173.5 | M11: 1233395 | N11: =IFERROR(K11/(M11/30),0) -> 7.893138 | O11: 525082.99 | P11: 218.5 | Q11: 1538870 | R11: =IFERROR(O11/(Q11/31),0) -> 10.577614 | S11: 565647.99 | T11: 163.75 | U11: 1145662.5 | V11: =IFERROR(S11/(U11/31),0) -> 15.305631 | W11: 489302.54 | X11: 97.5 | Y11: 675555 | Z11: =IFERROR(W11/(Y11/30),0) -> 21.728914 | AA11: 13397.04 | AB11: 139.75 | AC11: 1012757.5 | AD11: =IFERROR(AA11/(AC11/31),0) -> 0.41007669 | AE11: 143613.25 | AF11: 169 | AG11: 1238930 | AH11: =IFERROR(AE11/(AG11/30),0) -> 3.4775149 | AI11: 295660.25 | AJ11: 161.85 | AK11: 1137194.5 | AL11: =IFERROR(AI11/(AK11/31),0) -> 8.0597187 | AM11: -54482.28 | AN11: 108 | AO11: 730560 | AP11: =IFERROR(AM11/(AO11/31),0) -> -2.3118576 | AQ11: 244944.23 | AR11: 200 | AS11: 1386910 | AT11: =IFERROR(AQ11/(AS11/28),0) -> 4.9451215 | AU11: 254784.71 | AV11: 201 | AW11: 1431375 | AX11: =IFERROR(AU11/(AW11/31),0) -> 5.5179991 | AY11: =G11+K11+O11+S11+W11+AA11+AE11+AI11+AM11+AQ11+AU11 -> 3124579.5 | AZ11: =H11+L11+P11+T11+X11+AB11+AF11+AJ11+AN11+AR11+AV11 -> 1833.5 | BA11: =I11+M11+Q11+U11+Y11+AC11+AG11+AK11+AO11+AS11+AW11 -> 12946230 | BB11: =IFERROR(AY11/(BA11/31),0) -> 7.4818665 | BC11: ALWAR | BD11: ALWAR | BE11: RJ-JAIPUR
A12: 143807 | B12: KHAN TRADING COMPANY | C12: 138099.92 | D12: 20 | E12: 140400 | F12: =IFERROR(C12/(E12/30),0) -> 29.50853 | G12: 389.59 | H12: 10 | I12: 73950 | J12: =IFERROR(G12/(I12/31),0) -> 0.16331697 | K12: 78289.59 | L12: 20 | M12: 147200 | N12: =IFERROR(K12/(M12/30),0) -> 15.955759 | O12: 88122.63 | P12: 30 | Q12: 216600 | R12: =IFERROR(O12/(Q12/31),0) -> 12.612195 | S12: 61822.63 | T12: 20 | U12: 139400 | V12: =IFERROR(S12/(U12/31),0) -> 13.748218 | W12: 141522.63 | X12: 40 | Y12: 276400 | Z12: =IFERROR(W12/(Y12/30),0) -> 15.360633 | AA12: 254262.63 | AB12: 40 | AC12: 288200 | AD12: =IFERROR(AA12/(AC12/31),0) -> 27.349554 | AE12: 175612.68 | AF12: 30 | AG12: 224600 | AH12: =IFERROR(AE12/(AG12/30),0) -> 23.456725 | AI12: 119907.68 | AJ12: 50 | AK12: 362100 | AL12: =IFERROR(AI12/(AK12/31),0) -> 10.265501 | AM12: 176557.68 | AN12: 50 | AO12: 341100 | AP12: =IFERROR(AM12/(AO12/31),0) -> 16.045993 | AQ12: 187807.68 | AR12: 50 | AS12: 350650 | AT12: =IFERROR(AQ12/(AS12/28),0) -> 14.996763 | AU12: 169512.66 | AV12: 56 | AW12: 409230 | AX12: =IFERROR(AU12/(AW12/31),0) -> 12.840927 | AY12: =G12+K12+O12+S12+W12+AA12+AE12+AI12+AM12+AQ12+AU12 -> 1453808.1 | AZ12: =H12+L12+P12+T12+X12+AB12+AF12+AJ12+AN12+AR12+AV12 -> 396 | BA12: =I12+M12+Q12+U12+Y12+AC12+AG12+AK12+AO12+AS12+AW12 -> 2829430 | BB12: =IFERROR(AY12/(BA12/31),0) -> 15.928314 | BC12: ALWAR | BD12: ALWAR | BE12: RJ-JAIPUR
A13: 145198 | B13: RATHORE CONSTRUCTION | C13: 55288.27 | D13: 0 | E13: 0 | F13: =IFERROR(C13/(E13/30),0) -> 0 | G13: 161048.27 | H13: 40 | I13: 290500 | J13: =IFERROR(G13/(I13/31),0) -> 17.185874 | K13: 258588.27 | L13: 53 | M13: 378610 | N13: =IFERROR(K13/(M13/30),0) -> 20.489813 | O13: 263991.31 | P13: 50 | Q13: 353400 | R13: =IFERROR(O13/(Q13/31),0) -> 23.157132 | S13: 140891.31 | T13: 10 | U13: 69700 | V13: =IFERROR(S13/(U13/31),0) -> 62.66328 | W13: 212971.31 | X13: 43 | Y13: 298660 | Z13: =IFERROR(W13/(Y13/30),0) -> 21.392685 | AA13: 191551.31 | AB13: 32 | AC13: 230940 | AD13: =IFERROR(AA13/(AC13/31),0) -> 25.712699 | AE13: 168702.13 | AF13: 25 | AG13: 183550 | AH13: =IFERROR(AE13/(AG13/30),0) -> 27.573217 | AI13: 0 | AJ13: 0 | AK13: 0 | AL13: =IFERROR(AI13/(AK13/31),0) -> 0 | AM13: 98572.13 | AN13: 20 | AO13: 136600 | AP13: =IFERROR(AM13/(AO13/31),0) -> 22.369956 | AQ13: 107272.13 | AR13: 10 | AS13: 72500 | AT13: =IFERROR(AQ13/(AS13/28),0) -> 41.429236 | AU13: 95230.13 | AV13: 20 | AW13: 140980 | AX13: =IFERROR(AU13/(AW13/31),0) -> 20.940091 | AY13: =G13+K13+O13+S13+W13+AA13+AE13+AI13+AM13+AQ13+AU13 -> 1698818.3 | AZ13: =H13+L13+P13+T13+X13+AB13+AF13+AJ13+AN13+AR13+AV13 -> 303 | BA13: =I13+M13+Q13+U13+Y13+AC13+AG13+AK13+AO13+AS13+AW13 -> 2155440 | BB13: =IFERROR(AY13/(BA13/31),0) -> 24.432769 | BC13: ALWAR | BD13: ALWAR | BE13: RJ-JAIPUR
A14: 147891 | B14: NEW SAINI TRADING COMPANY | C14: 70517.46 | D14: 30 | E14: 213350 | F14: =IFERROR(C14/(E14/30),0) -> 9.9157431 | G14: 45048.54 | H14: 42 | I14: 296840 | J14: =IFERROR(G14/(I14/31),0) -> 4.7045706 | K14: 185158.54 | L14: 85 | M14: 607500 | N14: =IFERROR(K14/(M14/30),0) -> 9.1436316 | O14: 201528.54 | P14: 76 | Q14: 555370 | R14: =IFERROR(O14/(Q14/31),0) -> 11.24905 | S14: 316123.54 | T14: 102 | U14: 742940 | V14: =IFERROR(S14/(U14/31),0) -> 13.190607 | W14: 203707.54 | X14: 114.9 | Y14: 850703 | Z14: =IFERROR(W14/(Y14/30),0) -> 7.1837365 | AA14: 295146.54 | AB14: 127 | AC14: 947690 | AD14: =IFERROR(AA14/(AC14/31),0) -> 9.6545735 | AE14: 356486.94 | AF14: 105 | AG14: 788100 | AH14: =IFERROR(AE14/(AG14/30),0) -> 13.570116 | AI14: 280950.94 | AJ14: 140 | AK14: 1002050 | AL14: =IFERROR(AI14/(AK14/31),0) -> 8.6916612 | AM14: 404803.94 | AN14: 136 | AO14: 936970 | AP14: =IFERROR(AM14/(AO14/31),0) -> 13.393089 | AQ14: 342991.97 | AR14: 131 | AS14: 903770 | AT14: =IFERROR(AQ14/(AS14/28),0) -> 10.626349 | AU14: -121300.97 | AV14: 70 | AW14: 505900 | AX14: =IFERROR(AU14/(AW14/31),0) -> -7.4329513 | AY14: =G14+K14+O14+S14+W14+AA14+AE14+AI14+AM14+AQ14+AU14 -> 2510646.1 | AZ14: =H14+L14+P14+T14+X14+AB14+AF14+AJ14+AN14+AR14+AV14 -> 1128.9 | BA14: =I14+M14+Q14+U14+Y14+AC14+AG14+AK14+AO14+AS14+AW14 -> 8137833 | BB14: =IFERROR(AY14/(BA14/31),0) -> 9.5639746 | BC14: ALWAR | BD14: ALWAR | BE14: RJ-JAIPUR
... A663: 203478 | B663: BHULLAR AND SONS | C663: 0 | D663: 0 | E663: 0 | F663: =IFERROR(C663/(E663/30),0) -> 0 | G663: 0 | H663: 0 | I663: 0 | J663: =IFERROR(G663/(I663/31),0) -> 0 | K663: 0 | L663: 0 | M663: 0 | N663: =IFERROR(K663/(M663/30),0) -> 0 | O663: -16475 | P663: 57.5 | Q663: 433025 | R663: =IFERROR(O663/(Q663/31),0) -> -1.1794354 | S663: -22340 | T663: 62 | U663: 463140 | V663: =IFERROR(S663/(U663/31),0) -> -1.4953146 | W663: 123815 | X663: 80.5 | Y663: 592285 | Z663: =IFERROR(W663/(Y663/30),0) -> 6.2713896 | AA663: 176600 | AB663: 32 | AC663: 240440 | AD663: =IFERROR(AA663/(AC663/31),0) -> 22.76909 | AE663: 177290 | AF663: 27 | AG663: 211490 | AH663: =IFERROR(AE663/(AG663/30),0) -> 25.148707 | AI663: 0 | AJ663: 0 | AK663: 0 | AL663: =IFERROR(AI663/(AK663/31),0) -> 0 | AM663: 0 | AN663: 0 | AO663: 0 | AP663: =IFERROR(AM663/(AO663/31),0) -> 0 | AQ663: 0 | AR663: 0 | AS663: 0 | AT663: =IFERROR(AQ663/(AS663/28),0) -> 0 | AU663: -13130 | AV663: 0 | AW663: 0 | AX663: =IFERROR(AU663/(AW663/31),0) -> 0 | AY663: =G663+K663+O663+S663+W663+AA663+AE663+AI663+AM663+AQ663+AU663 -> 425760 | AZ663: =H663+L663+P663+T663+X663+AB663+AF663+AJ663+AN663+AR663+AV663 -> 259 | BA663: =I663+M663+Q663+U663+Y663+AC663+AG663+AK663+AO663+AS663+AW663 -> 1940380 | BB663: =IFERROR(AY663/(BA663/31),0) -> 6.8020491 | BC663: SRI GANGANAGAR | BD663: SRI GANGANAGAR | BE663: RJ-SGNR
A664: 119029 | B664: LALLAMAL KANHYALAL & SONS | C664: -191569.54 | D664: 13.75 | E664: 97212.5 | F664: =IFERROR(C664/(E664/30),0) -> -59.118799 | G664: 48864.46 | H664: 506.95 | I664: 3541181.5 | J664: =IFERROR(G664/(I664/31),0) -> 0.42776634 | K664: -372996.04 | L664: 608 | M664: 4242515 | N664: -2.6375584 | O664: -332192.53 | P664: 628.75 | Q664: 4407447.5 | R664: -2.3364926 | S664: -285124.53 | T664: 530.15 | U664: 3641190.5 | V664: -2.4274644 | W664: -545901.43 | X664: 351 | Y664: 2402075 | Z664: -6.8178733 | AA664: -809098.43 | AB664: 463.5 | AC664: 3302675 | AD664: -7.5944655 | AE664: 180959.21 | AF664: 550.5 | AG664: 3976940 | AH664: 1.3650637 | AI664: -131226.29 | AJ664: 505.75 | AK664: 3421397.5 | AL664: -1.1889922 | AM664: 339169.2 | AN664: 326 | AO664: 2179260 | AP664: 4.824686 | AQ664: 282320.65 | AR664: 572.95 | AS664: 3934176.5 | AT664: 2.0093095 | AU664: -430021.54 | AV664: 466.55 | AW664: 3229732.5 | AX664: -4.1274835 | AY664: -2055247.3 | AZ664: 5510.1 | BA664: 38278591 | BB664: -1.6644465 | BC664: AJMER | BD664: AJMER | BE664: RJ-AJMER
A665: 119042 | B665: SARAS ENTERPRISES | C665: -451726.32 | D665: 0 | E665: 0 | F665: =IFERROR(C665/(E665/30),0) -> 0 | G665: -77626.32 | H665: 175 | I665: 1225000 | J665: =IFERROR(G665/(I665/31),0) -> -1.9644212 | K665: -404976.32 | L665: 252.5 | M665: 1768900 | N665: -6.8682738 | O665: -153501.32 | P665: 320 | Q665: 2237500 | R665: -2.1267222 | S665: -199041.32 | T665: 276.5 | U665: 1913050 | V665: -3.2253631 | W665: -294286.72 | X665: 414 | Y665: 2823500 | Z665: -3.126829 | AA665: -594163.72 | AB665: 199.5 | AC665: 1421900 | AD665: -12.953847 | AE665: -830622 | AF665: 159.5 | AG665: 1162750 | AH665: -21.430798 | AI665: -279877 | AJ665: 195 | AK665: 1322800 | AL665: -6.558956 | AM665: -291638.95 | AN665: 235 | AO665: 1588900 | AP665: -5.6899789 | AQ665: -207770.91 | AR665: 196.5 | AS665: 1358950 | AT665: -4.2809415 | AU665: -619905.84 | AV665: 208 | AW665: 1456340 | AX665: -13.195463 | AY665: -3953410.4 | AZ665: 2631.5 | BA665: 18279590 | BB665: -6.7045116 | BC665: AJMER | BD665: AJMER | BE665: RJ-AJMER
A666: 119179 | B666: KUMAWAT BUILDING MATERIALS | C666: -673598.82 | D666: 0 | E666: 0 | F666: =IFERROR(C666/(E666/30),0) -> 0 | G666: -39988.82 | H666: 132 | I666: 927140 | J666: =IFERROR(G666/(I666/31),0) -> -1.3370725 | K666: -95138.82 | L666: 209 | M666: 1471360 | N666: -1.9398139 | O666: -125378.82 | P666: 280 | Q666: 1963700 | R666: -1.9792959 | S666: -58828.82 | T666: 150 | U666: 1041000 | V666: -1.7518669 | W666: -107379.11 | X666: 160 | Y666: 1094400 | Z666: -2.9435063 | AA666: -67779.11 | AB666: 150 | AC666: 1069800 | AD666: -1.964061 | AE666: -47138.43 | AF666: 110 | AG666: 803400 | AH666: -1.7602102 | AI666: -109306.43 | AJ666: 151 | AK666: 1041740 | AL666: -3.2527304 | AM666: -92294.43 | AN666: 170 | AO666: 1150300 | AP666: -2.487288 | AQ666: -65479.38 | AR666: 151 | AS666: 1036840 | AT666: -1.7682792 | AU666: -230281.34 | AV666: 155 | AW666: 1086700 | AX666: -6.5691741 | AY666: -1038993.5 | AZ666: 1818 | BA666: 12686380 | BB666: -2.5388487 | BC666: AJMER | BD666: AJMER | BE666: RJ-AJMER
A667: 119182 | B667: M.K.TRADERS | C667: -48445.89 | D667: 0 | E667: 0 | F667: =IFERROR(C667/(E667/30),0) -> 0 | G667: -15190.89 | H667: 51 | I667: 358020 | J667: =IFERROR(G667/(I667/31),0) -> -1.3153388 | K667: 0 | L667: 51 | M667: 358840 | N667: 0 | O667: 0 | P667: 0 | Q667: 0 | R667: 0 | S667: -18770.89 | T667: 53 | U667: 366760 | V667: -1.5865896 | W667: -33560.89 | X667: 60 | Y667: 409200 | Z667: -2.4604758 | AA667: -6060.89 | AB667: 15 | AC667: 108600 | AD667: -1.7300883 | AE667: 114188.87 | AF667: 60 | AG667: 437700 | AH667: 7.8265161 | AI667: 21208.87 | AJ667: 76 | AK667: 516040 | AL667: 1.2740775 | AM667: 194098.87 | AN667: 80 | AO667: 541600 | AP667: 11.109795 | AQ667: 211448.87 | AR667: 60 | AS667: 415000 | AT667: 14.26643 | AU667: -69816.14 | AV667: 55 | AW667: 379900 | AX667: -5.6970264 | AY667: 397545.78 | AZ667: 561 | BA667: 3891660 | BB667: 3.1667513 | BC667: AJMER | BD667: AJMER | BE667: RJ-AJMER
A668: 119208 | B668: SURAJMAL TANSUKH RAI | C668: -3536128.3 | D668: 89.5 | E668: 622920 | F668: =IFERROR(C668/(E668/30),0) -> -170.30092 | G668: -89154.28 | H668: 1741.8 | I668: 12167183 | J668: =IFERROR(G668/(I668/31),0) -> -0.22715058 | K668: -1379361.3 | L668: 2182.7 | M668: 15285903 | N668: -2.7071242 | O668: -931746.64 | P668: 1926.8 | Q668: 13473803 | R668: -2.1437263 | S668: -533889.64 | T668: 1060.35 | U668: 7366370 | V668: -2.2467754 | W668: -1330183.2 | X668: 1529 | Y668: 10408418 | Z668: -3.8339637 | AA668: -1439080.7 | AB668: 1526.5 | AC668: 10875332 | AD668: -4.1020815 | AE668: 1139345.9 | AF668: 1605.25 | AG668: 11630430 | AH668: 2.9388749 | AI668: -917671.55 | AJ668: 1470.7 | AK668: 10031244 | AL668: -2.8359214 | AM668: -940398.14 | AN668: 1250.5 | AO668: 8413340 | AP668: -3.4650142 | AQ668: 1202913.2 | AR668: 1486.25 | AS668: 10262162 | AT668: 3.2821122 | AU668: -1262840.3 | AV668: 1359.2 | AW668: 9475844 | AX668: -4.1313524 | AY668: -6482066.6 | AZ668: 17139.05 | BA668: 119390029 | BB668: -1.6830892 | BC668: AJMER | BD668: AJMER | BE668: RJ-AJMER
A669: 119221 | B669: AKSHAY TRADERS | C669: -24787.09 | D669: 0 | E669: 0 | F669: =IFERROR(C669/(E669/30),0) -> 0 | G669: -18827.09 | H669: 7 | I669: 57190 | J669: =IFERROR(G669/(I669/31),0) -> -10.205277 | K669: -78392.09 | L669: 100.75 | M669: 712302.5 | N669: -3.3016348 | O669: -39493.62 | P669: 123 | Q669: 864910 | R669: -1.4155256 | S669: -70033.62 | T669: 184 | U669: 1284130 | V669: -1.6906717 | W669: 161416.88 | X669: 175.35 | Y669: 1206674.5 | Z669: 4.0131008 | AA669: 500133.37 | AB669: 187.5 | AC669: 1353075 | AD669: 11.458444 | AE669: 656942.24 | AF669: 100.5 | AG669: 734835 | AH669: 26.81999 | AI669: 113396.74 | AJ669: 38.25 | AK669: 261627.5 | AL669: 13.436275 | AM669: 130124.25 | AN669: 171 | AO669: 1157670 | AP669: 3.4844574 | AQ669: 225537.81 | AR669: 54 | AS669: 376180 | AT669: 16.787332 | AU669: 372258.27 | AV669: 152 | AW669: 1065355 | AX669: 10.832076 | AY669: 1953063.1 | AZ669: 1293.35 | BA669: 9073949.5 | BB669: 6.672393 | BC669: AJMER | BD669: AJMER | BE669: RJ-AJMER
A670: 119222 | B670: MITHU LAL ROOP CHAND | C670: 0 | D670: 0 | E670: 0 | F670: =IFERROR(C670/(E670/30),0) -> 0 | G670: 0 | H670: 0 | I670: 0 | J670: =IFERROR(G670/(I670/31),0) -> 0 | K670: -113247.39 | L670: 196.3 | M670: 1385141 | N670: -2.4527624 | O670: 462519.61 | P670: 301.2 | Q670: 2111784 | R670: 6.7895712 | S670: 698597.61 | T670: 184 | U670: 1279330 | V670: 16.928022 | W670: 402522.45 | X670: 221 | Y670: 1515920 | Z670: 7.9659042 | AA670: 1376877.4 | AB670: 323.5 | AC670: 2299995 | AD670: 18.557954 | AE670: 1948496.1 | AF670: 243.35 | AG670: 1778654.5 | AH670: 32.864665 | AI670: 1396241.1 | AJ670: 249.75 | AK670: 1721907.5 | AL670: 25.136934 | AM670: 1754748.1 | AN670: 210 | AO670: 1423950 | AP670: 38.201617 | AQ670: 1361078.2 | AR670: 180 | AS670: 1242450 | AT670: 30.673419 | AU670: 823751.17 | AV670: 252.5 | AW670: 1797565 | AX670: 14.206043 | AY670: 10111584 | AZ670: 2361.6 | BA670: 16556697 | BB670: 18.932467 | BC670: AJMER | BD670: AJMER | BE670: RJ-AJMER
A671: 119230 | B671: MAHAVEER STONE SUPPLIERS | C671: -10482.25 | D671: 0 | E671: 0 | F671: =IFERROR(C671/(E671/30),0) -> 0 | G671: -13432.25 | H671: 7.5 | I671: 53025 | J671: =IFERROR(G671/(I671/31),0) -> -7.8528949 | K671: -8957.25 | L671: 20 | M671: 141400 | N671: -1.9004066 | O671: -2898.99 | P671: 10 | Q671: 70200 | R671: -1.2801808 | S671: -7248.99 | T671: 15 | U671: 104550 | V671: -2.1493897 | W671: -3498.99 | X671: 10 | Y671: 68700 | Z671: -1.5279432 | AA671: -6898.99 | AB671: 15 | AC671: 107550 | AD671: -1.9885513 | AE671: -3888.99 | AF671: 6 | AG671: 44220 | AH671: -2.6383921 | AI671: -2748.99 | AJ671: 5 | AK671: 33850 | AL671: -2.5175388 | AM671: -1898.99 | AN671: 5 | AO671: 33850 | AP671: -1.7391046 | AQ671: 31101.01 | AR671: 5 | AS671: 34850 | AT671: 24.987899 | AU671: -8638.99 | AV671: 5 | AW671: 34650 | AX671: -7.7289665 | AY671: -29010.41 | AZ671: 103.5 | BA671: 726845 | BB671: -1.2372964 | BC671: AJMER | BD671: AJMER | BE671: RJ-AJMER
A672: 119405 | B672: MUKESH KUMAR RAKESH KUMAR | C672: -3671.34 | D672: 24 | E672: 169680 | F672: =IFERROR(C672/(E672/30),0) -> -0.64910537 | G672: -8876.34 | H672: 50 | I672: 351500 | J672: =IFERROR(G672/(I672/31),0) -> -0.78283511 | K672: 0 | L672: 50 | M672: 351000 | N672: 0 | O672: 0 | P672: 0 | Q672: 0 | R672: 0 | S672: 0 | T672: 0 | U672: 0 | V672: 0 | W672: -7226.34 | X672: 20 | Y672: 137400 | Z672: -1.5778035 | AA672: 0 | AB672: 0 | AC672: 0 | AD672: 0 | AE672: 0 | AF672: 0 | AG672: 0 | AH672: 0 | AI672: 0 | AJ672: 0 | AK672: 0 | AL672: 0 | AM672: -2425.99 | AN672: 20 | AO672: 135400 | AP672: -0.55543346 | AQ672: -9525.99 | AR672: 20 | AS672: 139400 | AT672: -1.9133983 | AU672: 32280.25 | AV672: 30 | AW672: 207900 | AX672: 4.8133129 | AY672: 4225.59 | AZ672: 190 | BA672: 1322600 | BB672: 0.099042258 | BC672: AJMER | BD672: AJMER | BE672: RJ-AJMER
A673: 140818 | B673: SANIK ENTERPRISES | C673: 152519.85 | D673: 0 | E673: 0 | F673: =IFERROR(C673/(E673/30),0) -> 0 | G673: 83279.85 | H673: 49 | I673: 343980 | J673: =IFERROR(G673/(I673/31),0) -> 7.5053066 | K673: -46420.15 | L673: 100 | M673: 702800 | N673: -1.981509 | O673: -22770.15 | P673: 70 | Q673: 487900 | R673: -1.4467609 | S673: -16470.15 | T673: 50 | U673: 346800 | V673: -1.4722452 | W673: -52670.19 | X673: 80 | Y673: 546800 | Z673: -2.8897324 | AA673: -19370.19 | AB673: 55 | AC673: 392400 | AD673: -1.5302648 | AE673: 47130.32 | AF673: 55 | AG673: 400700 | AH673: 3.528599 | AI673: 92460.32 | AJ673: 64 | AK673: 434960 | AL673: 6.5897322 | AM673: -15109.67 | AN673: 30 | AO673: 202500 | AP673: -2.3130853 | AQ673: 109790.33 | AR673: 80 | AS673: 549500 | AT673: 5.5944117 | AU673: 68970.32 | AV673: 70 | AW673: 489800 | AX673: 4.3652101 | AY673: 228820.64 | AZ673: 703 | BA673: 4898140 | BB673: 1.4481905 | BC673: AJMER | BD673: AJMER | BE673: RJ-AJMER
A674: 140829 | B674: SHREE YADEN BUILDING MATERIAL | C674: -302562.34 | D674: 0 | E674: 0 | F674: =IFERROR(C674/(E674/30),0) -> 0 | G674: 147737.66 | H674: 195 | I674: 1368900 | J674: =IFERROR(G674/(I674/31),0) -> 3.3456552 | K674: -94262.34 | L674: 210 | M674: 1474200 | N674: -1.9182405 | O674: -74162.34 | P674: 155 | Q674: 1083100 | R674: -2.1226411 | S674: -94662.34 | T674: 105 | U674: 726600 | V674: -4.0387181 | W674: -204062.39 | X674: 120 | Y674: 821650 | Z674: -7.4507049 | AA674: -227235.39 | AB674: 60 | AC674: 437700 | AD674: -16.093893 | AE674: -137138.99 | AF674: 110 | AG674: 802200 | AH674: -5.1286085 | AI674: -114714.99 | AJ674: 140 | AK674: 958550 | AL674: -3.7099418 | AM674: -57578.99 | AN674: 115 | AO674: 774300 | AP674: -2.3052418 | AQ674: -87507 | AR674: 111 | AS674: 761670 | AT674: -3.2168734 | AU674: -196803 | AV674: 101.5 | AW674: 710320 | AX674: -8.588936 | AY674: -1140390.1 | AZ674: 1422.5 | BA674: 9919190 | BB674: -3.5640101 | BC674: AJMER | BD674: AJMER | BE674: RJ-AJMER
A675: 140830 | B675: KRISHNA CEMENT SUPPLIERS | C675: -459396.34 | D675: 0 | E675: 0 | F675: =IFERROR(C675/(E675/30),0) -> 0 | G675: -68296.34 | H675: 227 | I675: 1593940 | J675: =IFERROR(G675/(I675/31),0) -> -1.3282724 | K675: -131416.34 | L675: 270 | M675: 1895400 | N675: -2.0800307 | O675: -80166.34 | P675: 200 | Q675: 1396200 | R675: -1.7799431 | S675: -77406.34 | T675: 194 | U675: 1342880 | V675: -1.7869032 | W675: -160826.7 | X675: 200 | Y675: 1364000 | Z675: -3.5372441 | AA675: -104765.7 | AB675: 245 | AC675: 1751400 | AD675: -1.8543661 | AE675: 171802.1 | AF675: 175 | AG675: 1273000 | AH675: 4.0487533 | AI675: -134615.9 | AJ675: 150 | AK675: 1027200 | AL675: -4.0625904 | AM675: -144507.9 | AN675: 265 | AO675: 1793200 | AP675: -2.4981848 | AQ675: 127975.1 | AR675: 209 | AS675: 1453060 | AT675: 2.4660391 | AU675: -307982.91 | AV675: 175 | AW675: 1246000 | AX675: -7.6624962 | AY675: -910207.27 | AZ675: 2310 | BA675: 16136280 | BB675: -1.7486326 | BC675: AJMER | BD675: AJMER | BE675: RJ-AJMER
... A919: 172274 | B919: SONAM KHAD BEEJ BHANDAR | C919: 0 | D919: 0 | E919: 0 | F919: =IFERROR(C919/(E919/30),0) -> 0 | G919: 0 | H919: 0 | I919: 0 | J919: =IFERROR(G919/(I919/31),0) -> 0 | K919: 0 | L919: 0 | M919: 0 | N919: 0 | O919: 0 | P919: 0 | Q919: 0 | R919: 0 | S919: -36631.26 | T919: 0 | U919: 0 | V919: 0 | W919: -5431.26 | X919: 20 | Y919: 142400 | Z919: -1.1442261 | AA919: 0 | AB919: 0 | AC919: 0 | AD919: 0 | AE919: -12380.86 | AF919: 30 | AG919: 227600 | AH919: -1.6319236 | AI919: 0 | AJ919: 0 | AK919: 0 | AL919: 0 | AM919: 0 | AN919: 0 | AO919: 0 | AP919: 0 | AQ919: 0 | AR919: 0 | AS919: 0 | AT919: 0 | AU919: 0 | AV919: 0 | AW919: 0 | AX919: 0 | AY919: -54443.38 | AZ919: 50 | BA919: 370000 | BB919: -4.5614724 | BC919: SAWAI MADHOPUR | BD919: SAWAI MADHOPUR | BE919: RJ-AJMER
